Workbook

Sheet Executive_Summary
A1: Nova Consumer Products - CFO Monthly Sales MIS
A2: ="Actuals "&Monthly_MIS!A9&" to "&Monthly_MIS!B4&" | INR | Synthetic data | Controls: "&Control_Checks!C3 -> Actuals 2025-01 to 2026-09 | INR | Synthetic data | Controls: ALL 51 CHECKS PASS
A3: ="Budget: original Sales_Budget is "&TEXT(Budget_Integrity!B5,"0.0")&"x actual revenue and is NOT used. Illustrative variance only against SYNTHETIC v2 (unapproved) - see Budget_vs_Actual_v2 / Budget_Integrity." -> Budget: original Sales_Budget is 7.1x actual revenue and is NOT used. Illustrative variance only against SYNTHETIC v2 (unapproved) - see Budget_vs_Actual_v2 / Budget_Integrity.
A4: Headline KPI | B4: Value | C4: Comment
A5: Net revenue (all actual months) | B5: =Monthly_MIS!E30 -> 42593025 | C5: Actual-status invoices only
A6: COGS | B6: =Monthly_MIS!F30 -> 27380595
A7: Gross profit | B7: =Monthly_MIS!G30 -> 15212430
A8: Gross profit % | B8: =Monthly_MIS!H30 -> 0.35715777
A9: ="YTD revenue "&Monthly_MIS!B5 -> YTD revenue 2026 | B9: =Monthly_MIS!E34 -> 18093974 | C9: Jan to latest actual month
A10: YTD revenue change vs prior-year YTD | B10: =Monthly_MIS!E37 -> -0.017839831 | C10: Like-for-like months
A11: YTD GP % change vs prior-year YTD | B11: =Monthly_MIS!H37 -> -0.11061348 | C11: Percentage points
A12: Control checks | B12: =Control_Checks!C3 -> ALL 51 CHECKS PASS | C12: See Control_Checks
A14: CFO commentary (128 words)
A15: OBSERVED (actuals Jan-2025 to Sep-2026, 21 months): Net revenue INR 4.26 crore, gross profit INR 1.52 crore, margin 35.7%. YTD Sep-2026 revenue INR 1.81 crore, -1.8% vs prior-year YTD; margin 35.7% vs 35.8%. Monthly revenue (INR 18.4-22.6 lakh) and margin (34.8%-36.6%) show no clear trend. Each product sells in one region only, so region and product effects overlap: North's -15.0% YTD is Body Lotion (-24.2%) against Soap 4-pack (+3.7%); South's lowest margin (33.1%) reflects Detergent 1kg (32.6%) and Biscuits 500g (34.0%).
A16: UNVERIFIED CAUSES: Drivers of these movements (pricing, promotions, distribution, input costs, mix) cannot be established from this data. Returns, rebates and GST are excluded. The original budget is not comparable (about 7x actuals; 42% sits in cells with no sales), so no approved budget variance is reported.
A17: Commentary is generated at build time from verified results and checked (150-word limit, every number traceable to the fact pack); it is static text. KPI tiles above are live formulas.
A19: Metric availability
A20: Metric | B20: Status | C20: Reason / note
A21: Monthly net revenue, COGS, gross profit, GP % | B21: Available | C21: Derived from Sales_Transactions (Actual rows).
A22: Region-wise and product-wise performance | B22: Available | C22: Region via Customer_Master; product/category via Product_Master.
A23: Gross sales, trade discounts, returns, rebates | B23: UNAVAILABLE | C23: Source revenue is already net (Units x Net_Price); no gross-to-net, returns or rebate fields exist. List_Price vs Net_Price gap is implied only, not a reported discount.
A24: GST / intercompany adjustments | B24: UNAVAILABLE | C24: Source README states revenue excludes GST and intercompany sales; no such data supplied.
A25: Budget variance (revenue / gross profit) | B25: ILLUSTRATIVE ONLY | C25: Original budget is not comparable (see Budget_Integrity). Variance exists only against a SYNTHETIC calibrated v2 budget that is unapproved - see Budget_vs_Actual_v2.
A26: Product-level budget | B26: UNAVAILABLE | C26: Budget is by Month x Region x Category only.
A27: Region vs product attribution | B27: LIMITED | C27: Each product sells in one region only in this source, so regional and product effects overlap.
A28: Operating profit / EBITDA | B28: OUT OF DAY-1 SCOPE | C28: Opex exists in source but no allocation basis to sales dimensions was provided.

Sheet Monthly_MIS
A1: Monthly Sales & Profitability MIS - Actuals only
A2: Nova Consumer Products (synthetic). INR. Net revenue excludes GST, returns, rebates and intercompany (per source README). Forecast and budget are excluded.
A4: Latest actual month (from Calendar) | B4: =LOOKUP(2,1/(Calendar!$E$2:$E$25="Actual"),Calendar!$A$2:$A$25) -> 2026-09
A5: Latest actual year | B5: =VALUE(LEFT(B4,4)) -> 2026
A6: Latest actual month no. | B6: =VALUE(RIGHT(B4,2)) -> 9
A8: Month | B8: Year | C8: Invoices | D8: Units | E8: Net Revenue (INR) | F8: COGS (INR) | G8: Gross Profit (INR) | H8: GP % | I8: MoM Revenue % | J8: YoY Revenue % | K8: YoY GP % change (pp) | L8: Check: raw-source revenue | M8: Check: raw-source COGS
A9: 2025-01 | B9: =INDEX(Calendar!$B$2:$B$25,MATCH(A9,Calendar!$A$2:$A$25,0)) -> 2025 | C9: =COUNTIFS(Calc_Actuals!$J$2:$J$865,B9,Calc_Actuals!$K$2:$K$865,VALUE(RIGHT(A9,2)),Calc_Actuals!$C$2:$C$865,"Actual") -> 36 | D9: =SUMIFS(Calc_Actuals!$M$2:$M$865,Calc_Actuals!$J$2:$J$865,B9,Calc_Actuals!$K$2:$K$865,VALUE(RIGHT(A9,2)),Calc_Actuals!$C$2:$C$865,"Actual") -> 11217 | E9: =SUMIFS(Calc_Actuals!$N$2:$N$865,Calc_Actuals!$J$2:$J$865,B9,Calc_Actuals!$K$2:$K$865,VALUE(RIGHT(A9,2)),Calc_Actuals!$C$2:$C$865,"Actual") -> 2235970.6 | F9: =SUMIFS(Calc_Actuals!$O$2:$O$865,Calc_Actuals!$J$2:$J$865,B9,Calc_Actuals!$K$2:$K$865,VALUE(RIGHT(A9,2)),Calc_Actuals!$C$2:$C$865,"Actual") -> 1450589 | G9: =E9-F9 -> 785381.64 | H9: =IF(E9=0,"n/a",G9/E9) -> 0.35124864 | I9: n/a | J9: n/a | K9: n/a | L9: =SUMPRODUCT((Sales_Transactions!$B$2:$B$865=A9)*(Sales_Transactions!$C$2:$C$865="Actual")*Sales_Transactions!$I$2:$I$865) -> 2235970.6 | M9: =SUMPRODUCT((Sales_Transactions!$B$2:$B$865=A9)*(Sales_Transactions!$C$2:$C$865="Actual")*Sales_Transactions!$J$2:$J$865) -> 1450589
A10: 2025-02 | B10: =INDEX(Calendar!$B$2:$B$25,MATCH(A10,Calendar!$A$2:$A$25,0)) -> 2025 | C10: =COUNTIFS(Calc_Actuals!$J$2:$J$865,B10,Calc_Actuals!$K$2:$K$865,VALUE(RIGHT(A10,2)),Calc_Actuals!$C$2:$C$865,"Actual") -> 36 | D10: =SUMIFS(Calc_Actuals!$M$2:$M$865,Calc_Actuals!$J$2:$J$865,B10,Calc_Actuals!$K$2:$K$865,VALUE(RIGHT(A10,2)),Calc_Actuals!$C$2:$C$865,"Actual") -> 10456 | E10: =SUMIFS(Calc_Actuals!$N$2:$N$865,Calc_Actuals!$J$2:$J$865,B10,Calc_Actuals!$K$2:$K$865,VALUE(RIGHT(A10,2)),Calc_Actuals!$C$2:$C$865,"Actual") -> 2186134.6 | F10: =SUMIFS(Calc_Actuals!$O$2:$O$865,Calc_Actuals!$J$2:$J$865,B10,Calc_Actuals!$K$2:$K$865,VALUE(RIGHT(A10,2)),Calc_Actuals!$C$2:$C$865,"Actual") -> 1399128.2 | G10: =E10-F10 -> 787006.33 | H10: =IF(E10=0,"n/a",G10/E10) -> 0.35999903 | I10: =E10/E9-1 -> -0.022288343 | J10: n/a | K10: n/a | L10: =SUMPRODUCT((Sales_Transactions!$B$2:$B$865=A10)*(Sales_Transactions!$C$2:$C$865="Actual")*Sales_Transactions!$I$2:$I$865) -> 2186134.6 | M10: =SUMPRODUCT((Sales_Transactions!$B$2:$B$865=A10)*(Sales_Transactions!$C$2:$C$865="Actual")*Sales_Transactions!$J$2:$J$865) -> 1399128.2
A11: 2025-03 | B11: =INDEX(Calendar!$B$2:$B$25,MATCH(A11,Calendar!$A$2:$A$25,0)) -> 2025 | C11: =COUNTIFS(Calc_Actuals!$J$2:$J$865,B11,Calc_Actuals!$K$2:$K$865,VALUE(RIGHT(A11,2)),Calc_Actuals!$C$2:$C$865,"Actual") -> 36 | D11: =SUMIFS(Calc_Actuals!$M$2:$M$865,Calc_Actuals!$J$2:$J$865,B11,Calc_Actuals!$K$2:$K$865,VALUE(RIGHT(A11,2)),Calc_Actuals!$C$2:$C$865,"Actual") -> 9508 | E11: =SUMIFS(Calc_Actuals!$N$2:$N$865,Calc_Actuals!$J$2:$J$865,B11,Calc_Actuals!$K$2:$K$865,VALUE(RIGHT(A11,2)),Calc_Actuals!$C$2:$C$865,"Actual") -> 1892456.3 | F11: =SUMIFS(Calc_Actuals!$O$2:$O$865,Calc_Actuals!$J$2:$J$865,B11,Calc_Actuals!$K$2:$K$865,VALUE(RIGHT(A11,2)),Calc_Actuals!$C$2:$C$865,"Actual") -> 1233925.1 | G11: =E11-F11 -> 658531.2 | H11: =IF(E11=0,"n/a",G11/E11) -> 0.34797696 | I11: =E11/E10-1 -> -0.13433677 | J11: n/a | K11: n/a | L11: =SUMPRODUCT((Sales_Transactions!$B$2:$B$865=A11)*(Sales_Transactions!$C$2:$C$865="Actual")*Sales_Transactions!$I$2:$I$865) -> 1892456.3 | M11: =SUMPRODUCT((Sales_Transactions!$B$2:$B$865=A11)*(Sales_Transactions!$C$2:$C$865="Actual")*Sales_Transactions!$J$2:$J$865) -> 1233925.1
A12: 2025-04 | B12: =INDEX(Calendar!$B$2:$B$25,MATCH(A12,Calendar!$A$2:$A$25,0)) -> 2025 | C12: =COUNTIFS(Calc_Actuals!$J$2:$J$865,B12,Calc_Actuals!$K$2:$K$865,VALUE(RIGHT(A12,2)),Calc_Actuals!$C$2:$C$865,"Actual") -> 36 | D12: =SUMIFS(Calc_Actuals!$M$2:$M$865,Calc_Actuals!$J$2:$J$865,B12,Calc_Actuals!$K$2:$K$865,VALUE(RIGHT(A12,2)),Calc_Actuals!$C$2:$C$865,"Actual") -> 9553 | E12: =SUMIFS(Calc_Actuals!$N$2:$N$865,Calc_Actuals!$J$2:$J$865,B12,Calc_Actuals!$K$2:$K$865,VALUE(RIGHT(A12,2)),Calc_Actuals!$C$2:$C$865,"Actual") -> 2046367.5 | F12: =SUMIFS(Calc_Actuals!$O$2:$O$865,Calc_Actuals!$J$2:$J$865,B12,Calc_Actuals!$K$2:$K$865,VALUE(RIGHT(A12,2)),Calc_Actuals!$C$2:$C$865,"Actual") -> 1304778.8 | G12: =E12-F12 -> 741588.7 | H12: =IF(E12=0,"n/a",G12/E12) -> 0.36239273 | I12: =E12/E11-1 -> 0.081328794 | J12: n/a | K12: n/a | L12: =SUMPRODUCT((Sales_Transactions!$B$2:$B$865=A12)*(Sales_Transactions!$C$2:$C$865="Actual")*Sales_Transactions!$I$2:$I$865) -> 2046367.5 | M12: =SUMPRODUCT((Sales_Transactions!$B$2:$B$865=A12)*(Sales_Transactions!$C$2:$C$865="Actual")*Sales_Transactions!$J$2:$J$865) -> 1304778.8
A13: 2025-05 | B13: =INDEX(Calendar!$B$2:$B$25,MATCH(A13,Calendar!$A$2:$A$25,0)) -> 2025 | C13: =COUNTIFS(Calc_Actuals!$J$2:$J$865,B13,Calc_Actuals!$K$2:$K$865,VALUE(RIGHT(A13,2)),Calc_Actuals!$C$2:$C$865,"Actual") -> 36 | D13: =SUMIFS(Calc_Actuals!$M$2:$M$865,Calc_Actuals!$J$2:$J$865,B13,Calc_Actuals!$K$2:$K$865,VALUE(RIGHT(A13,2)),Calc_Actuals!$C$2:$C$865,"Actual") -> 9461 | E13: =SUMIFS(Calc_Actuals!$N$2:$N$865,Calc_Actuals!$J$2:$J$865,B13,Calc_Actuals!$K$2:$K$865,VALUE(RIGHT(A13,2)),Calc_Actuals!$C$2:$C$865,"Actual") -> 1854769 | F13: =SUMIFS(Calc_Actuals!$O$2:$O$865,Calc_Actuals!$J$2:$J$865,B13,Calc_Actuals!$K$2:$K$865,VALUE(RIGHT(A13,2)),Calc_Actuals!$C$2:$C$865,"Actual") -> 1176459.1 | G13: =E13-F13 -> 678309.89 | H13: =IF(E13=0,"n/a",G13/E13) -> 0.36571125 | I13: =E13/E12-1 -> -0.093628588 | J13: n/a | K13: n/a | L13: =SUMPRODUCT((Sales_Transactions!$B$2:$B$865=A13)*(Sales_Transactions!$C$2:$C$865="Actual")*Sales_Transactions!$I$2:$I$865) -> 1854769 | M13: =SUMPRODUCT((Sales_Transactions!$B$2:$B$865=A13)*(Sales_Transactions!$C$2:$C$865="Actual")*Sales_Transactions!$J$2:$J$865) -> 1176459.1
A14: 2025-06 | B14: =INDEX(Calendar!$B$2:$B$25,MATCH(A14,Calendar!$A$2:$A$25,0)) -> 2025 | C14: =COUNTIFS(Calc_Actuals!$J$2:$J$865,B14,Calc_Actuals!$K$2:$K$865,VALUE(RIGHT(A14,2)),Calc_Actuals!$C$2:$C$865,"Actual") -> 36 | D14: =SUMIFS(Calc_Actuals!$M$2:$M$865,Calc_Actuals!$J$2:$J$865,B14,Calc_Actuals!$K$2:$K$865,VALUE(RIGHT(A14,2)),Calc_Actuals!$C$2:$C$865,"Actual") -> 10213 | E14: =SUMIFS(Calc_Actuals!$N$2:$N$865,Calc_Actuals!$J$2:$J$865,B14,Calc_Actuals!$K$2:$K$865,VALUE(RIGHT(A14,2)),Calc_Actuals!$C$2:$C$865,"Actual") -> 2022308.5 | F14: =SUMIFS(Calc_Actuals!$O$2:$O$865,Calc_Actuals!$J$2:$J$865,B14,Calc_Actuals!$K$2:$K$865,VALUE(RIGHT(A14,2)),Calc_Actuals!$C$2:$C$865,"Actual") -> 1307599.9 | G14: =E14-F14 -> 714708.53 | H14: =IF(E14=0,"n/a",G14/E14) -> 0.35341222 | I14: =E14/E13-1 -> 0.090329027 | J14: n/a | K14: n/a | L14: =SUMPRODUCT((Sales_Transactions!$B$2:$B$865=A14)*(Sales_Transactions!$C$2:$C$865="Actual")*Sales_Transactions!$I$2:$I$865) -> 2022308.5 | M14: =SUMPRODUCT((Sales_Transactions!$B$2:$B$865=A14)*(Sales_Transactions!$C$2:$C$865="Actual")*Sales_Transactions!$J$2:$J$865) -> 1307599.9
A15: 2025-07 | B15: =INDEX(Calendar!$B$2:$B$25,MATCH(A15,Calendar!$A$2:$A$25,0)) -> 2025 | C15: =COUNTIFS(Calc_Actuals!$J$2:$J$865,B15,Calc_Actuals!$K$2:$K$865,VALUE(RIGHT(A15,2)),Calc_Actuals!$C$2:$C$865,"Actual") -> 36 | D15: =SUMIFS(Calc_Actuals!$M$2:$M$865,Calc_Actuals!$J$2:$J$865,B15,Calc_Actuals!$K$2:$K$865,VALUE(RIGHT(A15,2)),Calc_Actuals!$C$2:$C$865,"Actual") -> 10255 | E15: =SUMIFS(Calc_Actuals!$N$2:$N$865,Calc_Actuals!$J$2:$J$865,B15,Calc_Actuals!$K$2:$K$865,VALUE(RIGHT(A15,2)),Calc_Actuals!$C$2:$C$865,"Actual") -> 2118994.9 | F15: =SUMIFS(Calc_Actuals!$O$2:$O$865,Calc_Actuals!$J$2:$J$865,B15,Calc_Actuals!$K$2:$K$865,VALUE(RIGHT(A15,2)),Calc_Actuals!$C$2:$C$865,"Actual") -> 1359634 | G15: =E15-F15 -> 759360.9 | H15: =IF(E15=0,"n/a",G15/E15) -> 0.358359 | I15: =E15/E14-1 -> 0.047809941 | J15: n/a | K15: n/a | L15: =SUMPRODUCT((Sales_Transactions!$B$2:$B$865=A15)*(Sales_Transactions!$C$2:$C$865="Actual")*Sales_Transactions!$I$2:$I$865) -> 2118994.9 | M15: =SUMPRODUCT((Sales_Transactions!$B$2:$B$865=A15)*(Sales_Transactions!$C$2:$C$865="Actual")*Sales_Transactions!$J$2:$J$865) -> 1359634
A16: 2025-08 | B16: =INDEX(Calendar!$B$2:$B$25,MATCH(A16,Calendar!$A$2:$A$25,0)) -> 2025 | C16: =COUNTIFS(Calc_Actuals!$J$2:$J$865,B16,Calc_Actuals!$K$2:$K$865,VALUE(RIGHT(A16,2)),Calc_Actuals!$C$2:$C$865,"Actual") -> 36 | D16: =SUMIFS(Calc_Actuals!$M$2:$M$865,Calc_Actuals!$J$2:$J$865,B16,Calc_Actuals!$K$2:$K$865,VALUE(RIGHT(A16,2)),Calc_Actuals!$C$2:$C$865,"Actual") -> 10467 | E16: =SUMIFS(Calc_Actuals!$N$2:$N$865,Calc_Actuals!$J$2:$J$865,B16,Calc_Actuals!$K$2:$K$865,VALUE(RIGHT(A16,2)),Calc_Actuals!$C$2:$C$865,"Actual") -> 2077890.7 | F16: =SUMIFS(Calc_Actuals!$O$2:$O$865,Calc_Actuals!$J$2:$J$865,B16,Calc_Actuals!$K$2:$K$865,VALUE(RIGHT(A16,2)),Calc_Actuals!$C$2:$C$865,"Actual") -> 1330203.5 | G16: =E16-F16 -> 747687.24 | H16: =IF(E16=0,"n/a",G16/E16) -> 0.35982991 | I16: =E16/E15-1 -> -0.019397975 | J16: n/a | K16: n/a | L16: =SUMPRODUCT((Sales_Transactions!$B$2:$B$865=A16)*(Sales_Transactions!$C$2:$C$865="Actual")*Sales_Transactions!$I$2:$I$865) -> 2077890.7 | M16: =SUMPRODUCT((Sales_Transactions!$B$2:$B$865=A16)*(Sales_Transactions!$C$2:$C$865="Actual")*Sales_Transactions!$J$2:$J$865) -> 1330203.5
A17: 2025-09 | B17: =INDEX(Calendar!$B$2:$B$25,MATCH(A17,Calendar!$A$2:$A$25,0)) -> 2025 | C17: =COUNTIFS(Calc_Actuals!$J$2:$J$865,B17,Calc_Actuals!$K$2:$K$865,VALUE(RIGHT(A17,2)),Calc_Actuals!$C$2:$C$865,"Actual") -> 36 | D17: =SUMIFS(Calc_Actuals!$M$2:$M$865,Calc_Actuals!$J$2:$J$865,B17,Calc_Actuals!$K$2:$K$865,VALUE(RIGHT(A17,2)),Calc_Actuals!$C$2:$C$865,"Actual") -> 9666 | E17: =SUMIFS(Calc_Actuals!$N$2:$N$865,Calc_Actuals!$J$2:$J$865,B17,Calc_Actuals!$K$2:$K$865,VALUE(RIGHT(A17,2)),Calc_Actuals!$C$2:$C$865,"Actual") -> 1987738.3 | F17: =SUMIFS(Calc_Actuals!$O$2:$O$865,Calc_Actuals!$J$2:$J$865,B17,Calc_Actuals!$K$2:$K$865,VALUE(RIGHT(A17,2)),Calc_Actuals!$C$2:$C$865,"Actual") -> 1261139.1 | G17: =E17-F17 -> 726599.29 | H17: =IF(E17=0,"n/a",G17/E17) -> 0.36554071 | I17: =E17/E16-1 -> -0.043386488 | J17: n/a | K17: n/a | L17: =SUMPRODUCT((Sales_Transactions!$B$2:$B$865=A17)*(Sales_Transactions!$C$2:$C$865="Actual")*Sales_Transactions!$I$2:$I$865) -> 1987738.3 | M17: =SUMPRODUCT((Sales_Transactions!$B$2:$B$865=A17)*(Sales_Transactions!$C$2:$C$865="Actual")*Sales_Transactions!$J$2:$J$865) -> 1261139.1
A18: 2025-10 | B18: =INDEX(Calendar!$B$2:$B$25,MATCH(A18,Calendar!$A$2:$A$25,0)) -> 2025 | C18: =COUNTIFS(Calc_Actuals!$J$2:$J$865,B18,Calc_Actuals!$K$2:$K$865,VALUE(RIGHT(A18,2)),Calc_Actuals!$C$2:$C$865,"Actual") -> 36 | D18: =SUMIFS(Calc_Actuals!$M$2:$M$865,Calc_Actuals!$J$2:$J$865,B18,Calc_Actuals!$K$2:$K$865,VALUE(RIGHT(A18,2)),Calc_Actuals!$C$2:$C$865,"Actual") -> 9279 | E18: =SUMIFS(Calc_Actuals!$N$2:$N$865,Calc_Actuals!$J$2:$J$865,B18,Calc_Actuals!$K$2:$K$865,VALUE(RIGHT(A18,2)),Calc_Actuals!$C$2:$C$865,"Actual") -> 1869248.2 | F18: =SUMIFS(Calc_Actuals!$O$2:$O$865,Calc_Actuals!$J$2:$J$865,B18,Calc_Actuals!$K$2:$K$865,VALUE(RIGHT(A18,2)),Calc_Actuals!$C$2:$C$865,"Actual") -> 1205962.6 | G18: =E18-F18 -> 663285.56 | H18: =IF(E18=0,"n/a",G18/E18) -> 0.35484082 | I18: =E18/E17-1 -> -0.059610547 | J18: n/a | K18: n/a | L18: =SUMPRODUCT((Sales_Transactions!$B$2:$B$865=A18)*(Sales_Transactions!$C$2:$C$865="Actual")*Sales_Transactions!$I$2:$I$865) -> 1869248.2 | M18: =SUMPRODUCT((Sales_Transactions!$B$2:$B$865=A18)*(Sales_Transactions!$C$2:$C$865="Actual")*Sales_Transactions!$J$2:$J$865) -> 1205962.6
A19: 2025-11 | B19: =INDEX(Calendar!$B$2:$B$25,MATCH(A19,Calendar!$A$2:$A$25,0)) -> 2025 | C19: =COUNTIFS(Calc_Actuals!$J$2:$J$865,B19,Calc_Actuals!$K$2:$K$865,VALUE(RIGHT(A19,2)),Calc_Actuals!$C$2:$C$865,"Actual") -> 36 | D19: =SUMIFS(Calc_Actuals!$M$2:$M$865,Calc_Actuals!$J$2:$J$865,B19,Calc_Actuals!$K$2:$K$865,VALUE(RIGHT(A19,2)),Calc_Actuals!$C$2:$C$865,"Actual") -> 9797 | E19: =SUMIFS(Calc_Actuals!$N$2:$N$865,Calc_Actuals!$J$2:$J$865,B19,Calc_Actuals!$K$2:$K$865,VALUE(RIGHT(A19,2)),Calc_Actuals!$C$2:$C$865,"Actual") -> 2011362.9 | F19: =SUMIFS(Calc_Actuals!$O$2:$O$865,Calc_Actuals!$J$2:$J$865,B19,Calc_Actuals!$K$2:$K$865,VALUE(RIGHT(A19,2)),Calc_Actuals!$C$2:$C$865,"Actual") -> 1312045 | G19: =E19-F19 -> 699317.88 | H19: =IF(E19=0,"n/a",G19/E19) -> 0.34768359 | I19: =E19/E18-1 -> 0.076027759 | J19: n/a | K19: n/a | L19: =SUMPRODUCT((Sales_Transactions!$B$2:$B$865=A19)*(Sales_Transactions!$C$2:$C$865="Actual")*Sales_Transactions!$I$2:$I$865) -> 2011362.9 | M19: =SUMPRODUCT((Sales_Transactions!$B$2:$B$865=A19)*(Sales_Transactions!$C$2:$C$865="Actual")*Sales_Transactions!$J$2:$J$865) -> 1312045
A20: 2025-12 | B20: =INDEX(Calendar!$B$2:$B$25,MATCH(A20,Calendar!$A$2:$A$25,0)) -> 2025 | C20: =COUNTIFS(Calc_Actuals!$J$2:$J$865,B20,Calc_Actuals!$K$2:$K$865,VALUE(RIGHT(A20,2)),Calc_Actuals!$C$2:$C$865,"Actual") -> 36 | D20: =SUMIFS(Calc_Actuals!$M$2:$M$865,Calc_Actuals!$J$2:$J$865,B20,Calc_Actuals!$K$2:$K$865,VALUE(RIGHT(A20,2)),Calc_Actuals!$C$2:$C$865,"Actual") -> 10675 | E20: =SUMIFS(Calc_Actuals!$N$2:$N$865,Calc_Actuals!$J$2:$J$865,B20,Calc_Actuals!$K$2:$K$865,VALUE(RIGHT(A20,2)),Calc_Actuals!$C$2:$C$865,"Actual") -> 2195809.8 | F20: =SUMIFS(Calc_Actuals!$O$2:$O$865,Calc_Actuals!$J$2:$J$865,B20,Calc_Actuals!$K$2:$K$865,VALUE(RIGHT(A20,2)),Calc_Actuals!$C$2:$C$865,"Actual") -> 1406588.1 | G20: =E20-F20 -> 789221.75 | H20: =IF(E20=0,"n/a",G20/E20) -> 0.35942172 | I20: =E20/E19-1 -> 0.091702451 | J20: n/a | K20: n/a | L20: =SUMPRODUCT((Sales_Transactions!$B$2:$B$865=A20)*(Sales_Transactions!$C$2:$C$865="Actual")*Sales_Transactions!$I$2:$I$865) -> 2195809.8 | M20: =SUMPRODUCT((Sales_Transactions!$B$2:$B$865=A20)*(Sales_Transactions!$C$2:$C$865="Actual")*Sales_Transactions!$J$2:$J$865) -> 1406588.1
A21: 2026-01 | B21: =INDEX(Calendar!$B$2:$B$25,MATCH(A21,Calendar!$A$2:$A$25,0)) -> 2026 | C21: =COUNTIFS(Calc_Actuals!$J$2:$J$865,B21,Calc_Actuals!$K$2:$K$865,VALUE(RIGHT(A21,2)),Calc_Actuals!$C$2:$C$865,"Actual") -> 36 | D21: =SUMIFS(Calc_Actuals!$M$2:$M$865,Calc_Actuals!$J$2:$J$865,B21,Calc_Actuals!$K$2:$K$865,VALUE(RIGHT(A21,2)),Calc_Actuals!$C$2:$C$865,"Actual") -> 9570 | E21: =SUMIFS(Calc_Actuals!$N$2:$N$865,Calc_Actuals!$J$2:$J$865,B21,Calc_Actuals!$K$2:$K$865,VALUE(RIGHT(A21,2)),Calc_Actuals!$C$2:$C$865,"Actual") -> 1873462.9 | F21: =SUMIFS(Calc_Actuals!$O$2:$O$865,Calc_Actuals!$J$2:$J$865,B21,Calc_Actuals!$K$2:$K$865,VALUE(RIGHT(A21,2)),Calc_Actuals!$C$2:$C$865,"Actual") -> 1205508.1 | G21: =E21-F21 -> 667954.83 | H21: =IF(E21=0,"n/a",G21/E21) -> 0.35653485 | I21: =E21/E20-1 -> -0.14680091 | J21: =E21/E9-1 -> -0.16212543 | K21: =(H21-H9)*100 -> 0.52862134 | L21: =SUMPRODUCT((Sales_Transactions!$B$2:$B$865=A21)*(Sales_Transactions!$C$2:$C$865="Actual")*Sales_Transactions!$I$2:$I$865) -> 1873462.9 | M21: =SUMPRODUCT((Sales_Transactions!$B$2:$B$865=A21)*(Sales_Transactions!$C$2:$C$865="Actual")*Sales_Transactions!$J$2:$J$865) -> 1205508.1
A22: 2026-02 | B22: =INDEX(Calendar!$B$2:$B$25,MATCH(A22,Calendar!$A$2:$A$25,0)) -> 2026 | C22: =COUNTIFS(Calc_Actuals!$J$2:$J$865,B22,Calc_Actuals!$K$2:$K$865,VALUE(RIGHT(A22,2)),Calc_Actuals!$C$2:$C$865,"Actual") -> 36 | D22: =SUMIFS(Calc_Actuals!$M$2:$M$865,Calc_Actuals!$J$2:$J$865,B22,Calc_Actuals!$K$2:$K$865,VALUE(RIGHT(A22,2)),Calc_Actuals!$C$2:$C$865,"Actual") -> 9703 | E22: =SUMIFS(Calc_Actuals!$N$2:$N$865,Calc_Actuals!$J$2:$J$865,B22,Calc_Actuals!$K$2:$K$865,VALUE(RIGHT(A22,2)),Calc_Actuals!$C$2:$C$865,"Actual") -> 2004732 | F22: =SUMIFS(Calc_Actuals!$O$2:$O$865,Calc_Actuals!$J$2:$J$865,B22,Calc_Actuals!$K$2:$K$865,VALUE(RIGHT(A22,2)),Calc_Actuals!$C$2:$C$865,"Actual") -> 1285728.7 | G22: =E22-F22 -> 719003.36 | H22: =IF(E22=0,"n/a",G22/E22) -> 0.3586531 | I22: =E22/E21-1 -> 0.070067609 | J22: =E22/E10-1 -> -0.082978675 | K22: =(H22-H10)*100 -> -0.13459293 | L22: =SUMPRODUCT((Sales_Transactions!$B$2:$B$865=A22)*(Sales_Transactions!$C$2:$C$865="Actual")*Sales_Transactions!$I$2:$I$865) -> 2004732 | M22: =SUMPRODUCT((Sales_Transactions!$B$2:$B$865=A22)*(Sales_Transactions!$C$2:$C$865="Actual")*Sales_Transactions!$J$2:$J$865) -> 1285728.7
A23: 2026-03 | B23: =INDEX(Calendar!$B$2:$B$25,MATCH(A23,Calendar!$A$2:$A$25,0)) -> 2026 | C23: =COUNTIFS(Calc_Actuals!$J$2:$J$865,B23,Calc_Actuals!$K$2:$K$865,VALUE(RIGHT(A23,2)),Calc_Actuals!$C$2:$C$865,"Actual") -> 36 | D23: =SUMIFS(Calc_Actuals!$M$2:$M$865,Calc_Actuals!$J$2:$J$865,B23,Calc_Actuals!$K$2:$K$865,VALUE(RIGHT(A23,2)),Calc_Actuals!$C$2:$C$865,"Actual") -> 9712 | E23: =SUMIFS(Calc_Actuals!$N$2:$N$865,Calc_Actuals!$J$2:$J$865,B23,Calc_Actuals!$K$2:$K$865,VALUE(RIGHT(A23,2)),Calc_Actuals!$C$2:$C$865,"Actual") -> 1984215.8 | F23: =SUMIFS(Calc_Actuals!$O$2:$O$865,Calc_Actuals!$J$2:$J$865,B23,Calc_Actuals!$K$2:$K$865,VALUE(RIGHT(A23,2)),Calc_Actuals!$C$2:$C$865,"Actual") -> 1276181.4 | G23: =E23-F23 -> 708034.31 | H23: =IF(E23=0,"n/a",G23/E23) -> 0.35683333 | I23: =E23/E22-1 -> -0.010233916 | J23: =E23/E11-1 -> 0.048486958 | K23: =(H23-H11)*100 -> 0.88563631 | L23: =SUMPRODUCT((Sales_Transactions!$B$2:$B$865=A23)*(Sales_Transactions!$C$2:$C$865="Actual")*Sales_Transactions!$I$2:$I$865) -> 1984215.8 | M23: =SUMPRODUCT((Sales_Transactions!$B$2:$B$865=A23)*(Sales_Transactions!$C$2:$C$865="Actual")*Sales_Transactions!$J$2:$J$865) -> 1276181.4
A24: 2026-04 | B24: =INDEX(Calendar!$B$2:$B$25,MATCH(A24,Calendar!$A$2:$A$25,0)) -> 2026 | C24: =COUNTIFS(Calc_Actuals!$J$2:$J$865,B24,Calc_Actuals!$K$2:$K$865,VALUE(RIGHT(A24,2)),Calc_Actuals!$C$2:$C$865,"Actual") -> 36 | D24: =SUMIFS(Calc_Actuals!$M$2:$M$865,Calc_Actuals!$J$2:$J$865,B24,Calc_Actuals!$K$2:$K$865,VALUE(RIGHT(A24,2)),Calc_Actuals!$C$2:$C$865,"Actual") -> 9917 | E24: =SUMIFS(Calc_Actuals!$N$2:$N$865,Calc_Actuals!$J$2:$J$865,B24,Calc_Actuals!$K$2:$K$865,VALUE(RIGHT(A24,2)),Calc_Actuals!$C$2:$C$865,"Actual") -> 1938660.2 | F24: =SUMIFS(Calc_Actuals!$O$2:$O$865,Calc_Actuals!$J$2:$J$865,B24,Calc_Actuals!$K$2:$K$865,VALUE(RIGHT(A24,2)),Calc_Actuals!$C$2:$C$865,"Actual") -> 1254810.8 | G24: =E24-F24 -> 683849.4 | H24: =IF(E24=0,"n/a",G24/E24) -> 0.3527433 | I24: =E24/E23-1 -> -0.022958965 | J24: =E24/E12-1 -> -0.0526334 | K24: =(H24-H12)*100 -> -0.96494294 | L24: =SUMPRODUCT((Sales_Transactions!$B$2:$B$865=A24)*(Sales_Transactions!$C$2:$C$865="Actual")*Sales_Transactions!$I$2:$I$865) -> 1938660.2 | M24: =SUMPRODUCT((Sales_Transactions!$B$2:$B$865=A24)*(Sales_Transactions!$C$2:$C$865="Actual")*Sales_Transactions!$J$2:$J$865) -> 1254810.8
A25: 2026-05 | B25: =INDEX(Calendar!$B$2:$B$25,MATCH(A25,Calendar!$A$2:$A$25,0)) -> 2026 | C25: =COUNTIFS(Calc_Actuals!$J$2:$J$865,B25,Calc_Actuals!$K$2:$K$865,VALUE(RIGHT(A25,2)),Calc_Actuals!$C$2:$C$865,"Actual") -> 36 | D25: =SUMIFS(Calc_Actuals!$M$2:$M$865,Calc_Actuals!$J$2:$J$865,B25,Calc_Actuals!$K$2:$K$865,VALUE(RIGHT(A25,2)),Calc_Actuals!$C$2:$C$865,"Actual") -> 10484 | E25: =SUMIFS(Calc_Actuals!$N$2:$N$865,Calc_Actuals!$J$2:$J$865,B25,Calc_Actuals!$K$2:$K$865,VALUE(RIGHT(A25,2)),Calc_Actuals!$C$2:$C$865,"Actual") -> 2190614.6 | F25: =SUMIFS(Calc_Actuals!$O$2:$O$865,Calc_Actuals!$J$2:$J$865,B25,Calc_Actuals!$K$2:$K$865,VALUE(RIGHT(A25,2)),Calc_Actuals!$C$2:$C$865,"Actual") -> 1410747.9 | G25: =E25-F25 -> 779866.74 | H25: =IF(E25=0,"n/a",G25/E25) -> 0.35600363 | I25: =E25/E24-1 -> 0.12996314 | J25: =E25/E13-1 -> 0.18107138 | K25: =(H25-H13)*100 -> -0.9707623 | L25: =SUMPRODUCT((Sales_Transactions!$B$2:$B$865=A25)*(Sales_Transactions!$C$2:$C$865="Actual")*Sales_Transactions!$I$2:$I$865) -> 2190614.6 | M25: =SUMPRODUCT((Sales_Transactions!$B$2:$B$865=A25)*(Sales_Transactions!$C$2:$C$865="Actual")*Sales_Transactions!$J$2:$J$865) -> 1410747.9
A26: 2026-06 | B26: =INDEX(Calendar!$B$2:$B$25,MATCH(A26,Calendar!$A$2:$A$25,0)) -> 2026 | C26: =COUNTIFS(Calc_Actuals!$J$2:$J$865,B26,Calc_Actuals!$K$2:$K$865,VALUE(RIGHT(A26,2)),Calc_Actuals!$C$2:$C$865,"Actual") -> 36 | D26: =SUMIFS(Calc_Actuals!$M$2:$M$865,Calc_Actuals!$J$2:$J$865,B26,Calc_Actuals!$K$2:$K$865,VALUE(RIGHT(A26,2)),Calc_Actuals!$C$2:$C$865,"Actual") -> 9992 | E26: =SUMIFS(Calc_Actuals!$N$2:$N$865,Calc_Actuals!$J$2:$J$865,B26,Calc_Actuals!$K$2:$K$865,VALUE(RIGHT(A26,2)),Calc_Actuals!$C$2:$C$865,"Actual") -> 1949299 | F26: =SUMIFS(Calc_Actuals!$O$2:$O$865,Calc_Actuals!$J$2:$J$865,B26,Calc_Actuals!$K$2:$K$865,VALUE(RIGHT(A26,2)),Calc_Actuals!$C$2:$C$865,"Actual") -> 1269183.1 | G26: =E26-F26 -> 680115.93 | H26: =IF(E26=0,"n/a",G26/E26) -> 0.34890282 | I26: =E26/E25-1 -> -0.11015883 | J26: =E26/E14-1 -> -0.036102029 | K26: =(H26-H14)*100 -> -0.45094013 | L26: =SUMPRODUCT((Sales_Transactions!$B$2:$B$865=A26)*(Sales_Transactions!$C$2:$C$865="Actual")*Sales_Transactions!$I$2:$I$865) -> 1949299 | M26: =SUMPRODUCT((Sales_Transactions!$B$2:$B$865=A26)*(Sales_Transactions!$C$2:$C$865="Actual")*Sales_Transactions!$J$2:$J$865) -> 1269183.1
A27: 2026-07 | B27: =INDEX(Calendar!$B$2:$B$25,MATCH(A27,Calendar!$A$2:$A$25,0)) -> 2026 | C27: =COUNTIFS(Calc_Actuals!$J$2:$J$865,B27,Calc_Actuals!$K$2:$K$865,VALUE(RIGHT(A27,2)),Calc_Actuals!$C$2:$C$865,"Actual") -> 36 | D27: =SUMIFS(Calc_Actuals!$M$2:$M$865,Calc_Actuals!$J$2:$J$865,B27,Calc_Actuals!$K$2:$K$865,VALUE(RIGHT(A27,2)),Calc_Actuals!$C$2:$C$865,"Actual") -> 11177 | E27: =SUMIFS(Calc_Actuals!$N$2:$N$865,Calc_Actuals!$J$2:$J$865,B27,Calc_Actuals!$K$2:$K$865,VALUE(RIGHT(A27,2)),Calc_Actuals!$C$2:$C$865,"Actual") -> 2260040.8 | F27: =SUMIFS(Calc_Actuals!$O$2:$O$865,Calc_Actuals!$J$2:$J$865,B27,Calc_Actuals!$K$2:$K$865,VALUE(RIGHT(A27,2)),Calc_Actuals!$C$2:$C$865,"Actual") -> 1444160 | G27: =E27-F27 -> 815880.81 | H27: =IF(E27=0,"n/a",G27/E27) -> 0.36100269 | I27: =E27/E26-1 -> 0.15941205 | J27: =E27/E15-1 -> 0.066562623 | K27: =(H27-H15)*100 -> 0.26436943 | L27: =SUMPRODUCT((Sales_Transactions!$B$2:$B$865=A27)*(Sales_Transactions!$C$2:$C$865="Actual")*Sales_Transactions!$I$2:$I$865) -> 2260040.8 | M27: =SUMPRODUCT((Sales_Transactions!$B$2:$B$865=A27)*(Sales_Transactions!$C$2:$C$865="Actual")*Sales_Transactions!$J$2:$J$865) -> 1444160
A28: 2026-08 | B28: =INDEX(Calendar!$B$2:$B$25,MATCH(A28,Calendar!$A$2:$A$25,0)) -> 2026 | C28: =COUNTIFS(Calc_Actuals!$J$2:$J$865,B28,Calc_Actuals!$K$2:$K$865,VALUE(RIGHT(A28,2)),Calc_Actuals!$C$2:$C$865,"Actual") -> 36 | D28: =SUMIFS(Calc_Actuals!$M$2:$M$865,Calc_Actuals!$J$2:$J$865,B28,Calc_Actuals!$K$2:$K$865,VALUE(RIGHT(A28,2)),Calc_Actuals!$C$2:$C$865,"Actual") -> 10141 | E28: =SUMIFS(Calc_Actuals!$N$2:$N$865,Calc_Actuals!$J$2:$J$865,B28,Calc_Actuals!$K$2:$K$865,VALUE(RIGHT(A28,2)),Calc_Actuals!$C$2:$C$865,"Actual") -> 2055159.1 | F28: =SUMIFS(Calc_Actuals!$O$2:$O$865,Calc_Actuals!$J$2:$J$865,B28,Calc_Actuals!$K$2:$K$865,VALUE(RIGHT(A28,2)),Calc_Actuals!$C$2:$C$865,"Actual") -> 1317378.5 | G28: =E28-F28 -> 737780.56 | H28: =IF(E28=0,"n/a",G28/E28) -> 0.35898952 | I28: =E28/E27-1 -> -0.090653992 | J28: =E28/E16-1 -> -0.010939772 | K28: =(H28-H16)*100 -> -0.084039837 | L28: =SUMPRODUCT((Sales_Transactions!$B$2:$B$865=A28)*(Sales_Transactions!$C$2:$C$865="Actual")*Sales_Transactions!$I$2:$I$865) -> 2055159.1 | M28: =SUMPRODUCT((Sales_Transactions!$B$2:$B$865=A28)*(Sales_Transactions!$C$2:$C$865="Actual")*Sales_Transactions!$J$2:$J$865) -> 1317378.5
A29: 2026-09 | B29: =INDEX(Calendar!$B$2:$B$25,MATCH(A29,Calendar!$A$2:$A$25,0)) -> 2026 | C29: =COUNTIFS(Calc_Actuals!$J$2:$J$865,B29,Calc_Actuals!$K$2:$K$865,VALUE(RIGHT(A29,2)),Calc_Actuals!$C$2:$C$865,"Actual") -> 36 | D29: =SUMIFS(Calc_Actuals!$M$2:$M$865,Calc_Actuals!$J$2:$J$865,B29,Calc_Actuals!$K$2:$K$865,VALUE(RIGHT(A29,2)),Calc_Actuals!$C$2:$C$865,"Actual") -> 9534 | E29: =SUMIFS(Calc_Actuals!$N$2:$N$865,Calc_Actuals!$J$2:$J$865,B29,Calc_Actuals!$K$2:$K$865,VALUE(RIGHT(A29,2)),Calc_Actuals!$C$2:$C$865,"Actual") -> 1837789.4 | F29: =SUMIFS(Calc_Actuals!$O$2:$O$865,Calc_Actuals!$J$2:$J$865,B29,Calc_Actuals!$K$2:$K$865,VALUE(RIGHT(A29,2)),Calc_Actuals!$C$2:$C$865,"Actual") -> 1168844.2 | G29: =E29-F29 -> 668945.26 | H29: =IF(E29=0,"n/a",G29/E29) -> 0.36399451 | I29: =E29/E28-1 -> -0.10576779 | J29: =E29/E17-1 -> -0.075436941 | K29: =(H29-H17)*100 -> -0.15462066 | L29: =SUMPRODUCT((Sales_Transactions!$B$2:$B$865=A29)*(Sales_Transactions!$C$2:$C$865="Actual")*Sales_Transactions!$I$2:$I$865) -> 1837789.4 | M29: =SUMPRODUCT((Sales_Transactions!$B$2:$B$865=A29)*(Sales_Transactions!$C$2:$C$865="Actual")*Sales_Transactions!$J$2:$J$865) -> 1168844.2
A30: Total (actuals) | C30: =SUM(C9:C29) -> 756 | D30: =SUM(D9:D29) -> 210777 | E30: =SUM(E9:E29) -> 42593025 | F30: =SUM(F9:F29) -> 27380595 | G30: =SUM(G9:G29) -> 15212430 | H30: =G30/E30 -> 0.35715777 | L30: =SUM(L9:L29) -> 42593025 | M30: =SUM(M9:M29) -> 27380595
A32: Like-for-like period summary (actuals)
A33: Period | E33: Net Revenue (INR) | F33: COGS (INR) | G33: Gross Profit (INR) | H33: GP %
A34: ="YTD "&B5&" (Jan-"&TEXT(DATE(B5,B6,1),"mmm")&")" -> YTD 2026 (Jan-Sep) | E34: =SUMIFS(Calc_Actuals!$N$2:$N$865,Calc_Actuals!$C$2:$C$865,"Actual",Calc_Actuals!$J$2:$J$865,$B$5,Calc_Actuals!$K$2:$K$865,"<="&$B$6) -> 18093974 | F34: =SUMIFS(Calc_Actuals!$O$2:$O$865,Calc_Actuals!$C$2:$C$865,"Actual",Calc_Actuals!$J$2:$J$865,$B$5,Calc_Actuals!$K$2:$K$865,"<="&$B$6) -> 11632543 | G34: =E34-F34 -> 6461431.2 | H34: =IF(E34=0,"n/a",G34/E34) -> 0.35710404
A35: ="YTD "&(B5-1)&" (Jan-"&TEXT(DATE(B5,B6,1),"mmm")&")" -> YTD 2025 (Jan-Sep) | E35: =SUMIFS(Calc_Actuals!$N$2:$N$865,Calc_Actuals!$C$2:$C$865,"Actual",Calc_Actuals!$J$2:$J$865,($B$5-1),Calc_Actuals!$K$2:$K$865,"<="&$B$6) -> 18422630 | F35: =SUMIFS(Calc_Actuals!$O$2:$O$865,Calc_Actuals!$C$2:$C$865,"Actual",Calc_Actuals!$J$2:$J$865,($B$5-1),Calc_Actuals!$K$2:$K$865,"<="&$B$6) -> 11823457 | G35: =E35-F35 -> 6599173.7 | H35: =IF(E35=0,"n/a",G35/E35) -> 0.35821018
A36: ="Full year "&(B5-1) -> Full year 2025 | E36: =SUMIFS(Calc_Actuals!$N$2:$N$865,Calc_Actuals!$C$2:$C$865,"Actual",Calc_Actuals!$J$2:$J$865,($B$5-1)) -> 24499051 | F36: =SUMIFS(Calc_Actuals!$O$2:$O$865,Calc_Actuals!$C$2:$C$865,"Actual",Calc_Actuals!$J$2:$J$865,($B$5-1)) -> 15748053 | G36: =E36-F36 -> 8750998.9 | H36: =IF(E36=0,"n/a",G36/E36) -> 0.35719746
A37: YTD change (current vs prior) | E37: =IF(E35=0,"n/a",E34/E35-1) -> -0.017839831 | F37: =IF(F35=0,"n/a",F34/F35-1) -> -0.016147063 | G37: =IF(G35=0,"n/a",G34/G35-1) -> -0.020872692 | H37: =(H34-H35)*100 -> -0.11061348

Sheet Region_Performance
A1: Region-wise Performance - Actuals
A2: Actuals only. INR. Totals reconcile to Monthly_MIS (see Control_Checks). YTD = Jan to latest actual month; prior-year YTD is like-for-like.
A5: Region | B5: Net Revenue (INR) | C5: COGS (INR) | D5: Gross Profit (INR) | E5: GP % | F5: Revenue share | G5: YTD Revenue (current) | H5: YTD Revenue (prior) | I5: YTD Rev YoY % | J5: YTD GP % (current) | K5: YTD GP % (prior) | L5: GP % change (pp)
A6: East | B6: =SUMIFS(Calc_Actuals!$N$2:$N$865,Calc_Actuals!$F$2:$F$865,$A6,Calc_Actuals!$C$2:$C$865,"Actual") -> 10080346 | C6: =SUMIFS(Calc_Actuals!$O$2:$O$865,Calc_Actuals!$F$2:$F$865,$A6,Calc_Actuals!$C$2:$C$865,"Actual") -> 6410602.7 | D6: =B6-C6 -> 3669743 | E6: =IF(B6=0,"n/a",D6/B6) -> 0.36404932 | F6: =B6/B$10 -> 0.23666658 | G6: =SUMIFS(Calc_Actuals!$N$2:$N$865,Calc_Actuals!$F$2:$F$865,$A6,Calc_Actuals!$C$2:$C$865,"Actual",Calc_Actuals!$J$2:$J$865,Monthly_MIS!$B$5,Calc_Actuals!$K$2:$K$865,"<="&Monthly_MIS!$B$6) -> 4494059.7 | H6: =SUMIFS(Calc_Actuals!$N$2:$N$865,Calc_Actuals!$F$2:$F$865,$A6,Calc_Actuals!$C$2:$C$865,"Actual",Calc_Actuals!$J$2:$J$865,(Monthly_MIS!$B$5-1),Calc_Actuals!$K$2:$K$865,"<="&Monthly_MIS!$B$6) -> 4089303.9 | I6: =IF(H6=0,"n/a",G6/H6-1) -> 0.098979147 | J6: =IF(G6=0,"n/a",(SUMIFS(Calc_Actuals!$N$2:$N$865,Calc_Actuals!$F$2:$F$865,$A6,Calc_Actuals!$C$2:$C$865,"Actual",Calc_Actuals!$J$2:$J$865,Monthly_MIS!$B$5,Calc_Actuals!$K$2:$K$865,"<="&Monthly_MIS!$B$6)-SUMIFS(Calc_Actuals!$O$2:$O$865,Calc_Actuals!$F$2:$F$865,$A6,Calc_Actuals!$C$2:$C$865,"Actual",Calc_Actuals!$J$2:$J$865,Monthly_MIS!$B$5,Calc_Actuals!$K$2:$K$865,"<="&Monthly_MIS!$B$6))/G6) -> 0.3666296 | K6: =IF(H6=0,"n/a",(SUMIFS(Calc_Actuals!$N$2:$N$865,Calc_Actuals!$F$2:$F$865,$A6,Calc_Actuals!$C$2:$C$865,"Actual",Calc_Actuals!$J$2:$J$865,(Monthly_MIS!$B$5-1),Calc_Actuals!$K$2:$K$865,"<="&Monthly_MIS!$B$6)-SUMIFS(Calc_Actuals!$O$2:$O$865,Calc_Actuals!$F$2:$F$865,$A6,Calc_Actuals!$C$2:$C$865,"Actual",Calc_Actuals!$J$2:$J$865,(Monthly_MIS!$B$5-1),Calc_Actuals!$K$2:$K$865,"<="&Monthly_MIS!$B$6))/H6) -> 0.36185307 | L6: =IFERROR((J6-K6)*100,"n/a") -> 0.47765291
A7: North | B7: =SUMIFS(Calc_Actuals!$N$2:$N$865,Calc_Actuals!$F$2:$F$865,$A7,Calc_Actuals!$C$2:$C$865,"Actual") -> 12412351 | C7: =SUMIFS(Calc_Actuals!$O$2:$O$865,Calc_Actuals!$F$2:$F$865,$A7,Calc_Actuals!$C$2:$C$865,"Actual") -> 7869163.6 | D7: =B7-C7 -> 4543187.4 | E7: =IF(B7=0,"n/a",D7/B7) -> 0.3660215 | F7: =B7/B$10 -> 0.29141745 | G7: =SUMIFS(Calc_Actuals!$N$2:$N$865,Calc_Actuals!$F$2:$F$865,$A7,Calc_Actuals!$C$2:$C$865,"Actual",Calc_Actuals!$J$2:$J$865,Monthly_MIS!$B$5,Calc_Actuals!$K$2:$K$865,"<="&Monthly_MIS!$B$6) -> 4914886 | H7: =SUMIFS(Calc_Actuals!$N$2:$N$865,Calc_Actuals!$F$2:$F$865,$A7,Calc_Actuals!$C$2:$C$865,"Actual",Calc_Actuals!$J$2:$J$865,(Monthly_MIS!$B$5-1),Calc_Actuals!$K$2:$K$865,"<="&Monthly_MIS!$B$6) -> 5782011.6 | I7: =IF(H7=0,"n/a",G7/H7-1) -> -0.14996954 | J7: =IF(G7=0,"n/a",(SUMIFS(Calc_Actuals!$N$2:$N$865,Calc_Actuals!$F$2:$F$865,$A7,Calc_Actuals!$C$2:$C$865,"Actual",Calc_Actuals!$J$2:$J$865,Monthly_MIS!$B$5,Calc_Actuals!$K$2:$K$865,"<="&Monthly_MIS!$B$6)-SUMIFS(Calc_Actuals!$O$2:$O$865,Calc_Actuals!$F$2:$F$865,$A7,Calc_Actuals!$C$2:$C$865,"Actual",Calc_Actuals!$J$2:$J$865,Monthly_MIS!$B$5,Calc_Actuals!$K$2:$K$865,"<="&Monthly_MIS!$B$6))/G7) -> 0.36529582 | K7: =IF(H7=0,"n/a",(SUMIFS(Calc_Actuals!$N$2:$N$865,Calc_Actuals!$F$2:$F$865,$A7,Calc_Actuals!$C$2:$C$865,"Actual",Calc_Actuals!$J$2:$J$865,(Monthly_MIS!$B$5-1),Calc_Actuals!$K$2:$K$865,"<="&Monthly_MIS!$B$6)-SUMIFS(Calc_Actuals!$O$2:$O$865,Calc_Actuals!$F$2:$F$865,$A7,Calc_Actuals!$C$2:$C$865,"Actual",Calc_Actuals!$J$2:$J$865,(Monthly_MIS!$B$5-1),Calc_Actuals!$K$2:$K$865,"<="&Monthly_MIS!$B$6))/H7) -> 0.36990068 | L7: =IFERROR((J7-K7)*100,"n/a") -> -0.46048608
A8: South | B8: =SUMIFS(Calc_Actuals!$N$2:$N$865,Calc_Actuals!$F$2:$F$865,$A8,Calc_Actuals!$C$2:$C$865,"Actual") -> 8028818.4 | C8: =SUMIFS(Calc_Actuals!$O$2:$O$865,Calc_Actuals!$F$2:$F$865,$A8,Calc_Actuals!$C$2:$C$865,"Actual") -> 5375054 | D8: =B8-C8 -> 2653764.5 | E8: =IF(B8=0,"n/a",D8/B8) -> 0.33052989 | F8: =B8/B$10 -> 0.18850078 | G8: =SUMIFS(Calc_Actuals!$N$2:$N$865,Calc_Actuals!$F$2:$F$865,$A8,Calc_Actuals!$C$2:$C$865,"Actual",Calc_Actuals!$J$2:$J$865,Monthly_MIS!$B$5,Calc_Actuals!$K$2:$K$865,"<="&Monthly_MIS!$B$6) -> 3394026.8 | H8: =SUMIFS(Calc_Actuals!$N$2:$N$865,Calc_Actuals!$F$2:$F$865,$A8,Calc_Actuals!$C$2:$C$865,"Actual",Calc_Actuals!$J$2:$J$865,(Monthly_MIS!$B$5-1),Calc_Actuals!$K$2:$K$865,"<="&Monthly_MIS!$B$6) -> 3438531.2 | I8: =IF(H8=0,"n/a",G8/H8-1) -> -0.012942858 | J8: =IF(G8=0,"n/a",(SUMIFS(Calc_Actuals!$N$2:$N$865,Calc_Actuals!$F$2:$F$865,$A8,Calc_Actuals!$C$2:$C$865,"Actual",Calc_Actuals!$J$2:$J$865,Monthly_MIS!$B$5,Calc_Actuals!$K$2:$K$865,"<="&Monthly_MIS!$B$6)-SUMIFS(Calc_Actuals!$O$2:$O$865,Calc_Actuals!$F$2:$F$865,$A8,Calc_Actuals!$C$2:$C$865,"Actual",Calc_Actuals!$J$2:$J$865,Monthly_MIS!$B$5,Calc_Actuals!$K$2:$K$865,"<="&Monthly_MIS!$B$6))/G8) -> 0.33542824 | K8: =IF(H8=0,"n/a",(SUMIFS(Calc_Actuals!$N$2:$N$865,Calc_Actuals!$F$2:$F$865,$A8,Calc_Actuals!$C$2:$C$865,"Actual",Calc_Actuals!$J$2:$J$865,(Monthly_MIS!$B$5-1),Calc_Actuals!$K$2:$K$865,"<="&Monthly_MIS!$B$6)-SUMIFS(Calc_Actuals!$O$2:$O$865,Calc_Actuals!$F$2:$F$865,$A8,Calc_Actuals!$C$2:$C$865,"Actual",Calc_Actuals!$J$2:$J$865,(Monthly_MIS!$B$5-1),Calc_Actuals!$K$2:$K$865,"<="&Monthly_MIS!$B$6))/H8) -> 0.32679113 | L8: =IFERROR((J8-K8)*100,"n/a") -> 0.86371178
A9: West | B9: =SUMIFS(Calc_Actuals!$N$2:$N$865,Calc_Actuals!$F$2:$F$865,$A9,Calc_Actuals!$C$2:$C$865,"Actual") -> 12071510 | C9: =SUMIFS(Calc_Actuals!$O$2:$O$865,Calc_Actuals!$F$2:$F$865,$A9,Calc_Actuals!$C$2:$C$865,"Actual") -> 7725774.9 | D9: =B9-C9 -> 4345735.3 | E9: =IF(B9=0,"n/a",D9/B9) -> 0.3599993 | F9: =B9/B$10 -> 0.28341519 | G9: =SUMIFS(Calc_Actuals!$N$2:$N$865,Calc_Actuals!$F$2:$F$865,$A9,Calc_Actuals!$C$2:$C$865,"Actual",Calc_Actuals!$J$2:$J$865,Monthly_MIS!$B$5,Calc_Actuals!$K$2:$K$865,"<="&Monthly_MIS!$B$6) -> 5291001.4 | H9: =SUMIFS(Calc_Actuals!$N$2:$N$865,Calc_Actuals!$F$2:$F$865,$A9,Calc_Actuals!$C$2:$C$865,"Actual",Calc_Actuals!$J$2:$J$865,(Monthly_MIS!$B$5-1),Calc_Actuals!$K$2:$K$865,"<="&Monthly_MIS!$B$6) -> 5112783.8 | I9: =IF(H9=0,"n/a",G9/H9-1) -> 0.034857255 | J9: =IF(G9=0,"n/a",(SUMIFS(Calc_Actuals!$N$2:$N$865,Calc_Actuals!$F$2:$F$865,$A9,Calc_Actuals!$C$2:$C$865,"Actual",Calc_Actuals!$J$2:$J$865,Monthly_MIS!$B$5,Calc_Actuals!$K$2:$K$865,"<="&Monthly_MIS!$B$6)-SUMIFS(Calc_Actuals!$O$2:$O$865,Calc_Actuals!$F$2:$F$865,$A9,Calc_Actuals!$C$2:$C$865,"Actual",Calc_Actuals!$J$2:$J$865,Monthly_MIS!$B$5,Calc_Actuals!$K$2:$K$865,"<="&Monthly_MIS!$B$6))/G9) -> 0.35530819 | K9: =IF(H9=0,"n/a",(SUMIFS(Calc_Actuals!$N$2:$N$865,Calc_Actuals!$F$2:$F$865,$A9,Calc_Actuals!$C$2:$C$865,"Actual",Calc_Actuals!$J$2:$J$865,(Monthly_MIS!$B$5-1),Calc_Actuals!$K$2:$K$865,"<="&Monthly_MIS!$B$6)-SUMIFS(Calc_Actuals!$O$2:$O$865,Calc_Actuals!$F$2:$F$865,$A9,Calc_Actuals!$C$2:$C$865,"Actual",Calc_Actuals!$J$2:$J$865,(Monthly_MIS!$B$5-1),Calc_Actuals!$K$2:$K$865,"<="&Monthly_MIS!$B$6))/H9) -> 0.36320626 | L9: =IFERROR((J9-K9)*100,"n/a") -> -0.78980608
A10: Total | B10: =SUM(B6:B9) -> 42593025 | C10: =SUM(C6:C9) -> 27380595 | D10: =SUM(D6:D9) -> 15212430 | E10: =D10/B10 -> 0.35715777 | F10: =SUM(F6:F9) -> 1 | G10: =SUM(G6:G9) -> 18093974 | H10: =SUM(H6:H9) -> 18422630 | I10: =G10/H10-1 -> -0.017839831 | J10: =Monthly_MIS!H34 -> 0.35710404 | K10: =Monthly_MIS!H35 -> 0.35821018 | L10: =(J10-K10)*100 -> -0.11061348
A12: Monthly net revenue by region (INR, actuals)
A13: Region | B13: 2025-01 | C13: 2025-02 | D13: 2025-03 | E13: 2025-04 | F13: 2025-05 | G13: 2025-06 | H13: 2025-07 | I13: 2025-08 | J13: 2025-09 | K13: 2025-10 | L13: 2025-11 | M13: 2025-12 | N13: 2026-01 | O13: 2026-02 | P13: 2026-03 | Q13: 2026-04 | R13: 2026-05 | S13: 2026-06 | T13: 2026-07 | U13: 2026-08 | V13: 2026-09 | W13: Total
A14: East | B14: =SUMIFS(Calc_Actuals!$N$2:$N$865,Calc_Actuals!$F$2:$F$865,$A14,Calc_Actuals!$J$2:$J$865,VALUE(LEFT(B$13,4)),Calc_Actuals!$K$2:$K$865,VALUE(RIGHT(B$13,2)),Calc_Actuals!$C$2:$C$865,"Actual") -> 426907.65 | C14: =SUMIFS(Calc_Actuals!$N$2:$N$865,Calc_Actuals!$F$2:$F$865,$A14,Calc_Actuals!$J$2:$J$865,VALUE(LEFT(C$13,4)),Calc_Actuals!$K$2:$K$865,VALUE(RIGHT(C$13,2)),Calc_Actuals!$C$2:$C$865,"Actual") -> 535847.41 | D14: =SUMIFS(Calc_Actuals!$N$2:$N$865,Calc_Actuals!$F$2:$F$865,$A14,Calc_Actuals!$J$2:$J$865,VALUE(LEFT(D$13,4)),Calc_Actuals!$K$2:$K$865,VALUE(RIGHT(D$13,2)),Calc_Actuals!$C$2:$C$865,"Actual") -> 406990.53 | E14: =SUMIFS(Calc_Actuals!$N$2:$N$865,Calc_Actuals!$F$2:$F$865,$A14,Calc_Actuals!$J$2:$J$865,VALUE(LEFT(E$13,4)),Calc_Actuals!$K$2:$K$865,VALUE(RIGHT(E$13,2)),Calc_Actuals!$C$2:$C$865,"Actual") -> 454416.94 | F14: =SUMIFS(Calc_Actuals!$N$2:$N$865,Calc_Actuals!$F$2:$F$865,$A14,Calc_Actuals!$J$2:$J$865,VALUE(LEFT(F$13,4)),Calc_Actuals!$K$2:$K$865,VALUE(RIGHT(F$13,2)),Calc_Actuals!$C$2:$C$865,"Actual") -> 327736.2 | G14: =SUMIFS(Calc_Actuals!$N$2:$N$865,Calc_Actuals!$F$2:$F$865,$A14,Calc_Actuals!$J$2:$J$865,VALUE(LEFT(G$13,4)),Calc_Actuals!$K$2:$K$865,VALUE(RIGHT(G$13,2)),Calc_Actuals!$C$2:$C$865,"Actual") -> 582555.78 | H14: =SUMIFS(Calc_Actuals!$N$2:$N$865,Calc_Actuals!$F$2:$F$865,$A14,Calc_Actuals!$J$2:$J$865,VALUE(LEFT(H$13,4)),Calc_Actuals!$K$2:$K$865,VALUE(RIGHT(H$13,2)),Calc_Actuals!$C$2:$C$865,"Actual") -> 517879.3 | I14: =SUMIFS(Calc_Actuals!$N$2:$N$865,Calc_Actuals!$F$2:$F$865,$A14,Calc_Actuals!$J$2:$J$865,VALUE(LEFT(I$13,4)),Calc_Actuals!$K$2:$K$865,VALUE(RIGHT(I$13,2)),Calc_Actuals!$C$2:$C$865,"Actual") -> 404593.08 | ... V14: =SUMIFS(Calc_Actuals!$N$2:$N$865,Calc_Actuals!$F$2:$F$865,$A14,Calc_Actuals!$J$2:$J$865,VALUE(LEFT(V$13,4)),Calc_Actuals!$K$2:$K$865,VALUE(RIGHT(V$13,2)),Calc_Actuals!$C$2:$C$865,"Actual") -> 498877.72 | W14: =SUM(B14:V14) -> 10080346
A15: North | B15: =SUMIFS(Calc_Actuals!$N$2:$N$865,Calc_Actuals!$F$2:$F$865,$A15,Calc_Actuals!$J$2:$J$865,VALUE(LEFT(B$13,4)),Calc_Actuals!$K$2:$K$865,VALUE(RIGHT(B$13,2)),Calc_Actuals!$C$2:$C$865,"Actual") -> 745665.04 | C15: =SUMIFS(Calc_Actuals!$N$2:$N$865,Calc_Actuals!$F$2:$F$865,$A15,Calc_Actuals!$J$2:$J$865,VALUE(LEFT(C$13,4)),Calc_Actuals!$K$2:$K$865,VALUE(RIGHT(C$13,2)),Calc_Actuals!$C$2:$C$865,"Actual") -> 615537.71 | D15: =SUMIFS(Calc_Actuals!$N$2:$N$865,Calc_Actuals!$F$2:$F$865,$A15,Calc_Actuals!$J$2:$J$865,VALUE(LEFT(D$13,4)),Calc_Actuals!$K$2:$K$865,VALUE(RIGHT(D$13,2)),Calc_Actuals!$C$2:$C$865,"Actual") -> 628432.07 | E15: =SUMIFS(Calc_Actuals!$N$2:$N$865,Calc_Actuals!$F$2:$F$865,$A15,Calc_Actuals!$J$2:$J$865,VALUE(LEFT(E$13,4)),Calc_Actuals!$K$2:$K$865,VALUE(RIGHT(E$13,2)),Calc_Actuals!$C$2:$C$865,"Actual") -> 741614.98 | F15: =SUMIFS(Calc_Actuals!$N$2:$N$865,Calc_Actuals!$F$2:$F$865,$A15,Calc_Actuals!$J$2:$J$865,VALUE(LEFT(F$13,4)),Calc_Actuals!$K$2:$K$865,VALUE(RIGHT(F$13,2)),Calc_Actuals!$C$2:$C$865,"Actual") -> 589779.17 | G15: =SUMIFS(Calc_Actuals!$N$2:$N$865,Calc_Actuals!$F$2:$F$865,$A15,Calc_Actuals!$J$2:$J$865,VALUE(LEFT(G$13,4)),Calc_Actuals!$K$2:$K$865,VALUE(RIGHT(G$13,2)),Calc_Actuals!$C$2:$C$865,"Actual") -> 491732.37 | H15: =SUMIFS(Calc_Actuals!$N$2:$N$865,Calc_Actuals!$F$2:$F$865,$A15,Calc_Actuals!$J$2:$J$865,VALUE(LEFT(H$13,4)),Calc_Actuals!$K$2:$K$865,VALUE(RIGHT(H$13,2)),Calc_Actuals!$C$2:$C$865,"Actual") -> 694054.4 | I15: =SUMIFS(Calc_Actuals!$N$2:$N$865,Calc_Actuals!$F$2:$F$865,$A15,Calc_Actuals!$J$2:$J$865,VALUE(LEFT(I$13,4)),Calc_Actuals!$K$2:$K$865,VALUE(RIGHT(I$13,2)),Calc_Actuals!$C$2:$C$865,"Actual") -> 689586.75 | ... V15: =SUMIFS(Calc_Actuals!$N$2:$N$865,Calc_Actuals!$F$2:$F$865,$A15,Calc_Actuals!$J$2:$J$865,VALUE(LEFT(V$13,4)),Calc_Actuals!$K$2:$K$865,VALUE(RIGHT(V$13,2)),Calc_Actuals!$C$2:$C$865,"Actual") -> 526552.47 | W15: =SUM(B15:V15) -> 12412351
A16: South | B16: =SUMIFS(Calc_Actuals!$N$2:$N$865,Calc_Actuals!$F$2:$F$865,$A16,Calc_Actuals!$J$2:$J$865,VALUE(LEFT(B$13,4)),Calc_Actuals!$K$2:$K$865,VALUE(RIGHT(B$13,2)),Calc_Actuals!$C$2:$C$865,"Actual") -> 489873.7 | C16: =SUMIFS(Calc_Actuals!$N$2:$N$865,Calc_Actuals!$F$2:$F$865,$A16,Calc_Actuals!$J$2:$J$865,VALUE(LEFT(C$13,4)),Calc_Actuals!$K$2:$K$865,VALUE(RIGHT(C$13,2)),Calc_Actuals!$C$2:$C$865,"Actual") -> 339462.96 | D16: =SUMIFS(Calc_Actuals!$N$2:$N$865,Calc_Actuals!$F$2:$F$865,$A16,Calc_Actuals!$J$2:$J$865,VALUE(LEFT(D$13,4)),Calc_Actuals!$K$2:$K$865,VALUE(RIGHT(D$13,2)),Calc_Actuals!$C$2:$C$865,"Actual") -> 394147.11 | E16: =SUMIFS(Calc_Actuals!$N$2:$N$865,Calc_Actuals!$F$2:$F$865,$A16,Calc_Actuals!$J$2:$J$865,VALUE(LEFT(E$13,4)),Calc_Actuals!$K$2:$K$865,VALUE(RIGHT(E$13,2)),Calc_Actuals!$C$2:$C$865,"Actual") -> 278867.73 | F16: =SUMIFS(Calc_Actuals!$N$2:$N$865,Calc_Actuals!$F$2:$F$865,$A16,Calc_Actuals!$J$2:$J$865,VALUE(LEFT(F$13,4)),Calc_Actuals!$K$2:$K$865,VALUE(RIGHT(F$13,2)),Calc_Actuals!$C$2:$C$865,"Actual") -> 372684.01 | G16: =SUMIFS(Calc_Actuals!$N$2:$N$865,Calc_Actuals!$F$2:$F$865,$A16,Calc_Actuals!$J$2:$J$865,VALUE(LEFT(G$13,4)),Calc_Actuals!$K$2:$K$865,VALUE(RIGHT(G$13,2)),Calc_Actuals!$C$2:$C$865,"Actual") -> 358368.08 | H16: =SUMIFS(Calc_Actuals!$N$2:$N$865,Calc_Actuals!$F$2:$F$865,$A16,Calc_Actuals!$J$2:$J$865,VALUE(LEFT(H$13,4)),Calc_Actuals!$K$2:$K$865,VALUE(RIGHT(H$13,2)),Calc_Actuals!$C$2:$C$865,"Actual") -> 400129.96 | I16: =SUMIFS(Calc_Actuals!$N$2:$N$865,Calc_Actuals!$F$2:$F$865,$A16,Calc_Actuals!$J$2:$J$865,VALUE(LEFT(I$13,4)),Calc_Actuals!$K$2:$K$865,VALUE(RIGHT(I$13,2)),Calc_Actuals!$C$2:$C$865,"Actual") -> 406776 | ... V16: =SUMIFS(Calc_Actuals!$N$2:$N$865,Calc_Actuals!$F$2:$F$865,$A16,Calc_Actuals!$J$2:$J$865,VALUE(LEFT(V$13,4)),Calc_Actuals!$K$2:$K$865,VALUE(RIGHT(V$13,2)),Calc_Actuals!$C$2:$C$865,"Actual") -> 360347.41 | W16: =SUM(B16:V16) -> 8028818.4
A17: West | B17: =SUMIFS(Calc_Actuals!$N$2:$N$865,Calc_Actuals!$F$2:$F$865,$A17,Calc_Actuals!$J$2:$J$865,VALUE(LEFT(B$13,4)),Calc_Actuals!$K$2:$K$865,VALUE(RIGHT(B$13,2)),Calc_Actuals!$C$2:$C$865,"Actual") -> 573524.26 | C17: =SUMIFS(Calc_Actuals!$N$2:$N$865,Calc_Actuals!$F$2:$F$865,$A17,Calc_Actuals!$J$2:$J$865,VALUE(LEFT(C$13,4)),Calc_Actuals!$K$2:$K$865,VALUE(RIGHT(C$13,2)),Calc_Actuals!$C$2:$C$865,"Actual") -> 695286.49 | D17: =SUMIFS(Calc_Actuals!$N$2:$N$865,Calc_Actuals!$F$2:$F$865,$A17,Calc_Actuals!$J$2:$J$865,VALUE(LEFT(D$13,4)),Calc_Actuals!$K$2:$K$865,VALUE(RIGHT(D$13,2)),Calc_Actuals!$C$2:$C$865,"Actual") -> 462886.6 | E17: =SUMIFS(Calc_Actuals!$N$2:$N$865,Calc_Actuals!$F$2:$F$865,$A17,Calc_Actuals!$J$2:$J$865,VALUE(LEFT(E$13,4)),Calc_Actuals!$K$2:$K$865,VALUE(RIGHT(E$13,2)),Calc_Actuals!$C$2:$C$865,"Actual") -> 571467.85 | F17: =SUMIFS(Calc_Actuals!$N$2:$N$865,Calc_Actuals!$F$2:$F$865,$A17,Calc_Actuals!$J$2:$J$865,VALUE(LEFT(F$13,4)),Calc_Actuals!$K$2:$K$865,VALUE(RIGHT(F$13,2)),Calc_Actuals!$C$2:$C$865,"Actual") -> 564569.62 | G17: =SUMIFS(Calc_Actuals!$N$2:$N$865,Calc_Actuals!$F$2:$F$865,$A17,Calc_Actuals!$J$2:$J$865,VALUE(LEFT(G$13,4)),Calc_Actuals!$K$2:$K$865,VALUE(RIGHT(G$13,2)),Calc_Actuals!$C$2:$C$865,"Actual") -> 589652.25 | H17: =SUMIFS(Calc_Actuals!$N$2:$N$865,Calc_Actuals!$F$2:$F$865,$A17,Calc_Actuals!$J$2:$J$865,VALUE(LEFT(H$13,4)),Calc_Actuals!$K$2:$K$865,VALUE(RIGHT(H$13,2)),Calc_Actuals!$C$2:$C$865,"Actual") -> 506931.27 | I17: =SUMIFS(Calc_Actuals!$N$2:$N$865,Calc_Actuals!$F$2:$F$865,$A17,Calc_Actuals!$J$2:$J$865,VALUE(LEFT(I$13,4)),Calc_Actuals!$K$2:$K$865,VALUE(RIGHT(I$13,2)),Calc_Actuals!$C$2:$C$865,"Actual") -> 576934.89 | ... V17: =SUMIFS(Calc_Actuals!$N$2:$N$865,Calc_Actuals!$F$2:$F$865,$A17,Calc_Actuals!$J$2:$J$865,VALUE(LEFT(V$13,4)),Calc_Actuals!$K$2:$K$865,VALUE(RIGHT(V$13,2)),Calc_Actuals!$C$2:$C$865,"Actual") -> 452011.84 | W17: =SUM(B17:V17) -> 12071510
A18: Total | B18: =SUM(B14:B17) -> 2235970.6 | C18: =SUM(C14:C17) -> 2186134.6 | D18: =SUM(D14:D17) -> 1892456.3 | E18: =SUM(E14:E17) -> 2046367.5 | F18: =SUM(F14:F17) -> 1854769 | G18: =SUM(G14:G17) -> 2022308.5 | H18: =SUM(H14:H17) -> 2118994.9 | I18: =SUM(I14:I17) -> 2077890.7 | ... W18: =SUM(W14:W17) -> 42593025

Sheet Product_Performance
A1: Product-wise Performance - Actuals
A2: Actuals only. INR. Totals reconcile to Monthly_MIS (see Control_Checks). YTD = Jan to latest actual month; prior-year YTD is like-for-like.
A5: Product | B5: Category | C5: Net Revenue (INR) | D5: COGS (INR) | E5: Gross Profit (INR) | F5: GP % | G5: Revenue share | H5: YTD Revenue (current) | I5: YTD Revenue (prior) | J5: YTD Rev YoY % | K5: YTD GP % (current) | L5: YTD GP % (prior) | M5: GP % change (pp) | N5: Regions selling (actual)
A6: Detergent 1kg | B6: Home Care | C6: =SUMIFS(Calc_Actuals!$N$2:$N$865,Calc_Actuals!$I$2:$I$865,$A6,Calc_Actuals!$C$2:$C$865,"Actual") -> 5329802.4 | D6: =SUMIFS(Calc_Actuals!$O$2:$O$865,Calc_Actuals!$I$2:$I$865,$A6,Calc_Actuals!$C$2:$C$865,"Actual") -> 3592946 | E6: =C6-D6 -> 1736856.4 | F6: =IF(C6=0,"n/a",E6/C6) -> 0.32587632 | G6: =C6/C$14 -> 0.12513322 | H6: =SUMIFS(Calc_Actuals!$N$2:$N$865,Calc_Actuals!$I$2:$I$865,$A6,Calc_Actuals!$C$2:$C$865,"Actual",Calc_Actuals!$J$2:$J$865,Monthly_MIS!$B$5,Calc_Actuals!$K$2:$K$865,"<="&Monthly_MIS!$B$6) -> 2199515.3 | I6: =SUMIFS(Calc_Actuals!$N$2:$N$865,Calc_Actuals!$I$2:$I$865,$A6,Calc_Actuals!$C$2:$C$865,"Actual",Calc_Actuals!$J$2:$J$865,(Monthly_MIS!$B$5-1),Calc_Actuals!$K$2:$K$865,"<="&Monthly_MIS!$B$6) -> 2271071 | J6: =IF(I6=0,"n/a",H6/I6-1) -> -0.031507439 | K6: =IF(H6=0,"n/a",(SUMIFS(Calc_Actuals!$N$2:$N$865,Calc_Actuals!$I$2:$I$865,$A6,Calc_Actuals!$C$2:$C$865,"Actual",Calc_Actuals!$J$2:$J$865,Monthly_MIS!$B$5,Calc_Actuals!$K$2:$K$865,"<="&Monthly_MIS!$B$6)-SUMIFS(Calc_Actuals!$O$2:$O$865,Calc_Actuals!$I$2:$I$865,$A6,Calc_Actuals!$C$2:$C$865,"Actual",Calc_Actuals!$J$2:$J$865,Monthly_MIS!$B$5,Calc_Actuals!$K$2:$K$865,"<="&Monthly_MIS!$B$6))/H6) -> 0.33089589 | L6: =IF(I6=0,"n/a",(SUMIFS(Calc_Actuals!$N$2:$N$865,Calc_Actuals!$I$2:$I$865,$A6,Calc_Actuals!$C$2:$C$865,"Actual",Calc_Actuals!$J$2:$J$865,(Monthly_MIS!$B$5-1),Calc_Actuals!$K$2:$K$865,"<="&Monthly_MIS!$B$6)-SUMIFS(Calc_Actuals!$O$2:$O$865,Calc_Actuals!$I$2:$I$865,$A6,Calc_Actuals!$C$2:$C$865,"Actual",Calc_Actuals!$J$2:$J$865,(Monthly_MIS!$B$5-1),Calc_Actuals!$K$2:$K$865,"<="&Monthly_MIS!$B$6))/I6) -> 0.32311368 | M6: =IFERROR((K6-L6)*100,"n/a") -> 0.77822067 | N6: =SUMPRODUCT(--(COUNTIFS(Calc_Actuals!$I$2:$I$865,$A6,Calc_Actuals!$F$2:$F$865,Region_Performance!$A$6:$A$9,Calc_Actuals!$C$2:$C$865,"Actual")>0)) -> 1
A7: Dishwash Gel | B7: Home Care | C7: =SUMIFS(Calc_Actuals!$N$2:$N$865,Calc_Actuals!$I$2:$I$865,$A7,Calc_Actuals!$C$2:$C$865,"Actual") -> 3716909.9 | D7: =SUMIFS(Calc_Actuals!$O$2:$O$865,Calc_Actuals!$I$2:$I$865,$A7,Calc_Actuals!$C$2:$C$865,"Actual") -> 2250619.4 | E7: =C7-D7 -> 1466290.5 | F7: =IF(C7=0,"n/a",E7/C7) -> 0.3944918 | G7: =C7/C$14 -> 0.087265694 | H7: =SUMIFS(Calc_Actuals!$N$2:$N$865,Calc_Actuals!$I$2:$I$865,$A7,Calc_Actuals!$C$2:$C$865,"Actual",Calc_Actuals!$J$2:$J$865,Monthly_MIS!$B$5,Calc_Actuals!$K$2:$K$865,"<="&Monthly_MIS!$B$6) -> 1565993.1 | I7: =SUMIFS(Calc_Actuals!$N$2:$N$865,Calc_Actuals!$I$2:$I$865,$A7,Calc_Actuals!$C$2:$C$865,"Actual",Calc_Actuals!$J$2:$J$865,(Monthly_MIS!$B$5-1),Calc_Actuals!$K$2:$K$865,"<="&Monthly_MIS!$B$6) -> 1598048.1 | J7: =IF(I7=0,"n/a",H7/I7-1) -> -0.020058846 | K7: =IF(H7=0,"n/a",(SUMIFS(Calc_Actuals!$N$2:$N$865,Calc_Actuals!$I$2:$I$865,$A7,Calc_Actuals!$C$2:$C$865,"Actual",Calc_Actuals!$J$2:$J$865,Monthly_MIS!$B$5,Calc_Actuals!$K$2:$K$865,"<="&Monthly_MIS!$B$6)-SUMIFS(Calc_Actuals!$O$2:$O$865,Calc_Actuals!$I$2:$I$865,$A7,Calc_Actuals!$C$2:$C$865,"Actual",Calc_Actuals!$J$2:$J$865,Monthly_MIS!$B$5,Calc_Actuals!$K$2:$K$865,"<="&Monthly_MIS!$B$6))/H7) -> 0.39172969 | L7: =IF(I7=0,"n/a",(SUMIFS(Calc_Actuals!$N$2:$N$865,Calc_Actuals!$I$2:$I$865,$A7,Calc_Actuals!$C$2:$C$865,"Actual",Calc_Actuals!$J$2:$J$865,(Monthly_MIS!$B$5-1),Calc_Actuals!$K$2:$K$865,"<="&Monthly_MIS!$B$6)-SUMIFS(Calc_Actuals!$O$2:$O$865,Calc_Actuals!$I$2:$I$865,$A7,Calc_Actuals!$C$2:$C$865,"Actual",Calc_Actuals!$J$2:$J$865,(Monthly_MIS!$B$5-1),Calc_Actuals!$K$2:$K$865,"<="&Monthly_MIS!$B$6))/I7) -> 0.39886388 | M7: =IFERROR((K7-L7)*100,"n/a") -> -0.71341813 | N7: =SUMPRODUCT(--(COUNTIFS(Calc_Actuals!$I$2:$I$865,$A7,Calc_Actuals!$F$2:$F$865,Region_Performance!$A$6:$A$9,Calc_Actuals!$C$2:$C$865,"Actual")>0)) -> 1
A8: Shampoo 400ml | B8: Personal Care | C8: =SUMIFS(Calc_Actuals!$N$2:$N$865,Calc_Actuals!$I$2:$I$865,$A8,Calc_Actuals!$C$2:$C$865,"Actual") -> 7438401 | D8: =SUMIFS(Calc_Actuals!$O$2:$O$865,Calc_Actuals!$I$2:$I$865,$A8,Calc_Actuals!$C$2:$C$865,"Actual") -> 4831935.2 | E8: =C8-D8 -> 2606465.9 | F8: =IF(C8=0,"n/a",E8/C8) -> 0.35040674 | G8: =C8/C$14 -> 0.17463895 | H8: =SUMIFS(Calc_Actuals!$N$2:$N$865,Calc_Actuals!$I$2:$I$865,$A8,Calc_Actuals!$C$2:$C$865,"Actual",Calc_Actuals!$J$2:$J$865,Monthly_MIS!$B$5,Calc_Actuals!$K$2:$K$865,"<="&Monthly_MIS!$B$6) -> 3312413.2 | I8: =SUMIFS(Calc_Actuals!$N$2:$N$865,Calc_Actuals!$I$2:$I$865,$A8,Calc_Actuals!$C$2:$C$865,"Actual",Calc_Actuals!$J$2:$J$865,(Monthly_MIS!$B$5-1),Calc_Actuals!$K$2:$K$865,"<="&Monthly_MIS!$B$6) -> 3035812.7 | J8: =IF(I8=0,"n/a",H8/I8-1) -> 0.091112526 | K8: =IF(H8=0,"n/a",(SUMIFS(Calc_Actuals!$N$2:$N$865,Calc_Actuals!$I$2:$I$865,$A8,Calc_Actuals!$C$2:$C$865,"Actual",Calc_Actuals!$J$2:$J$865,Monthly_MIS!$B$5,Calc_Actuals!$K$2:$K$865,"<="&Monthly_MIS!$B$6)-SUMIFS(Calc_Actuals!$O$2:$O$865,Calc_Actuals!$I$2:$I$865,$A8,Calc_Actuals!$C$2:$C$865,"Actual",Calc_Actuals!$J$2:$J$865,Monthly_MIS!$B$5,Calc_Actuals!$K$2:$K$865,"<="&Monthly_MIS!$B$6))/H8) -> 0.34466891 | L8: =IF(I8=0,"n/a",(SUMIFS(Calc_Actuals!$N$2:$N$865,Calc_Actuals!$I$2:$I$865,$A8,Calc_Actuals!$C$2:$C$865,"Actual",Calc_Actuals!$J$2:$J$865,(Monthly_MIS!$B$5-1),Calc_Actuals!$K$2:$K$865,"<="&Monthly_MIS!$B$6)-SUMIFS(Calc_Actuals!$O$2:$O$865,Calc_Actuals!$I$2:$I$865,$A8,Calc_Actuals!$C$2:$C$865,"Actual",Calc_Actuals!$J$2:$J$865,(Monthly_MIS!$B$5-1),Calc_Actuals!$K$2:$K$865,"<="&Monthly_MIS!$B$6))/I8) -> 0.35243399 | M8: =IFERROR((K8-L8)*100,"n/a") -> -0.77650755 | N8: =SUMPRODUCT(--(COUNTIFS(Calc_Actuals!$I$2:$I$865,$A8,Calc_Actuals!$F$2:$F$865,Region_Performance!$A$6:$A$9,Calc_Actuals!$C$2:$C$865,"Actual")>0)) -> 1
A9: Soap 4-pack | B9: Personal Care | C9: =SUMIFS(Calc_Actuals!$N$2:$N$865,Calc_Actuals!$I$2:$I$865,$A9,Calc_Actuals!$C$2:$C$865,"Actual") -> 4437357.5 | D9: =SUMIFS(Calc_Actuals!$O$2:$O$865,Calc_Actuals!$I$2:$I$865,$A9,Calc_Actuals!$C$2:$C$865,"Actual") -> 2578870 | E9: =C9-D9 -> 1858487.4 | F9: =IF(C9=0,"n/a",E9/C9) -> 0.41882753 | G9: =C9/C$14 -> 0.10418038 | H9: =SUMIFS(Calc_Actuals!$N$2:$N$865,Calc_Actuals!$I$2:$I$865,$A9,Calc_Actuals!$C$2:$C$865,"Actual",Calc_Actuals!$J$2:$J$865,Monthly_MIS!$B$5,Calc_Actuals!$K$2:$K$865,"<="&Monthly_MIS!$B$6) -> 1972313.7 | I9: =SUMIFS(Calc_Actuals!$N$2:$N$865,Calc_Actuals!$I$2:$I$865,$A9,Calc_Actuals!$C$2:$C$865,"Actual",Calc_Actuals!$J$2:$J$865,(Monthly_MIS!$B$5-1),Calc_Actuals!$K$2:$K$865,"<="&Monthly_MIS!$B$6) -> 1902277.8 | J9: =IF(I9=0,"n/a",H9/I9-1) -> 0.036816863 | K9: =IF(H9=0,"n/a",(SUMIFS(Calc_Actuals!$N$2:$N$865,Calc_Actuals!$I$2:$I$865,$A9,Calc_Actuals!$C$2:$C$865,"Actual",Calc_Actuals!$J$2:$J$865,Monthly_MIS!$B$5,Calc_Actuals!$K$2:$K$865,"<="&Monthly_MIS!$B$6)-SUMIFS(Calc_Actuals!$O$2:$O$865,Calc_Actuals!$I$2:$I$865,$A9,Calc_Actuals!$C$2:$C$865,"Actual",Calc_Actuals!$J$2:$J$865,Monthly_MIS!$B$5,Calc_Actuals!$K$2:$K$865,"<="&Monthly_MIS!$B$6))/H9) -> 0.41103137 | L9: =IF(I9=0,"n/a",(SUMIFS(Calc_Actuals!$N$2:$N$865,Calc_Actuals!$I$2:$I$865,$A9,Calc_Actuals!$C$2:$C$865,"Actual",Calc_Actuals!$J$2:$J$865,(Monthly_MIS!$B$5-1),Calc_Actuals!$K$2:$K$865,"<="&Monthly_MIS!$B$6)-SUMIFS(Calc_Actuals!$O$2:$O$865,Calc_Actuals!$I$2:$I$865,$A9,Calc_Actuals!$C$2:$C$865,"Actual",Calc_Actuals!$J$2:$J$865,(Monthly_MIS!$B$5-1),Calc_Actuals!$K$2:$K$865,"<="&Monthly_MIS!$B$6))/I9) -> 0.4263669 | M9: =IFERROR((K9-L9)*100,"n/a") -> -1.5335527 | N9: =SUMPRODUCT(--(COUNTIFS(Calc_Actuals!$I$2:$I$865,$A9,Calc_Actuals!$F$2:$F$865,Region_Performance!$A$6:$A$9,Calc_Actuals!$C$2:$C$865,"Actual")>0)) -> 1
A10: Biscuits 500g | B10: Foods | C10: =SUMIFS(Calc_Actuals!$N$2:$N$865,Calc_Actuals!$I$2:$I$865,$A10,Calc_Actuals!$C$2:$C$865,"Actual") -> 2699016 | D10: =SUMIFS(Calc_Actuals!$O$2:$O$865,Calc_Actuals!$I$2:$I$865,$A10,Calc_Actuals!$C$2:$C$865,"Actual") -> 1782108 | E10: =C10-D10 -> 916908.08 | F10: =IF(C10=0,"n/a",E10/C10) -> 0.33971939 | G10: =C10/C$14 -> 0.063367559 | H10: =SUMIFS(Calc_Actuals!$N$2:$N$865,Calc_Actuals!$I$2:$I$865,$A10,Calc_Actuals!$C$2:$C$865,"Actual",Calc_Actuals!$J$2:$J$865,Monthly_MIS!$B$5,Calc_Actuals!$K$2:$K$865,"<="&Monthly_MIS!$B$6) -> 1194511.5 | I10: =SUMIFS(Calc_Actuals!$N$2:$N$865,Calc_Actuals!$I$2:$I$865,$A10,Calc_Actuals!$C$2:$C$865,"Actual",Calc_Actuals!$J$2:$J$865,(Monthly_MIS!$B$5-1),Calc_Actuals!$K$2:$K$865,"<="&Monthly_MIS!$B$6) -> 1167460.3 | J10: =IF(I10=0,"n/a",H10/I10-1) -> 0.02317099 | K10: =IF(H10=0,"n/a",(SUMIFS(Calc_Actuals!$N$2:$N$865,Calc_Actuals!$I$2:$I$865,$A10,Calc_Actuals!$C$2:$C$865,"Actual",Calc_Actuals!$J$2:$J$865,Monthly_MIS!$B$5,Calc_Actuals!$K$2:$K$865,"<="&Monthly_MIS!$B$6)-SUMIFS(Calc_Actuals!$O$2:$O$865,Calc_Actuals!$I$2:$I$865,$A10,Calc_Actuals!$C$2:$C$865,"Actual",Calc_Actuals!$J$2:$J$865,Monthly_MIS!$B$5,Calc_Actuals!$K$2:$K$865,"<="&Monthly_MIS!$B$6))/H10) -> 0.3437739 | L10: =IF(I10=0,"n/a",(SUMIFS(Calc_Actuals!$N$2:$N$865,Calc_Actuals!$I$2:$I$865,$A10,Calc_Actuals!$C$2:$C$865,"Actual",Calc_Actuals!$J$2:$J$865,(Monthly_MIS!$B$5-1),Calc_Actuals!$K$2:$K$865,"<="&Monthly_MIS!$B$6)-SUMIFS(Calc_Actuals!$O$2:$O$865,Calc_Actuals!$I$2:$I$865,$A10,Calc_Actuals!$C$2:$C$865,"Actual",Calc_Actuals!$J$2:$J$865,(Monthly_MIS!$B$5-1),Calc_Actuals!$K$2:$K$865,"<="&Monthly_MIS!$B$6))/I10) -> 0.33394489 | M10: =IFERROR((K10-L10)*100,"n/a") -> 0.98290112 | N10: =SUMPRODUCT(--(COUNTIFS(Calc_Actuals!$I$2:$I$865,$A10,Calc_Actuals!$F$2:$F$865,Region_Performance!$A$6:$A$9,Calc_Actuals!$C$2:$C$865,"Actual")>0)) -> 1
A11: Breakfast Cereal | B11: Foods | C11: =SUMIFS(Calc_Actuals!$N$2:$N$865,Calc_Actuals!$I$2:$I$865,$A11,Calc_Actuals!$C$2:$C$865,"Actual") -> 6363435.8 | D11: =SUMIFS(Calc_Actuals!$O$2:$O$865,Calc_Actuals!$I$2:$I$865,$A11,Calc_Actuals!$C$2:$C$865,"Actual") -> 4159983.2 | E11: =C11-D11 -> 2203452.5 | F11: =IF(C11=0,"n/a",E11/C11) -> 0.34626774 | G11: =C11/C$14 -> 0.14940089 | H11: =SUMIFS(Calc_Actuals!$N$2:$N$865,Calc_Actuals!$I$2:$I$865,$A11,Calc_Actuals!$C$2:$C$865,"Actual",Calc_Actuals!$J$2:$J$865,Monthly_MIS!$B$5,Calc_Actuals!$K$2:$K$865,"<="&Monthly_MIS!$B$6) -> 2928066.6 | I11: =SUMIFS(Calc_Actuals!$N$2:$N$865,Calc_Actuals!$I$2:$I$865,$A11,Calc_Actuals!$C$2:$C$865,"Actual",Calc_Actuals!$J$2:$J$865,(Monthly_MIS!$B$5-1),Calc_Actuals!$K$2:$K$865,"<="&Monthly_MIS!$B$6) -> 2491255.8 | J11: =IF(I11=0,"n/a",H11/I11-1) -> 0.1753376 | K11: =IF(H11=0,"n/a",(SUMIFS(Calc_Actuals!$N$2:$N$865,Calc_Actuals!$I$2:$I$865,$A11,Calc_Actuals!$C$2:$C$865,"Actual",Calc_Actuals!$J$2:$J$865,Monthly_MIS!$B$5,Calc_Actuals!$K$2:$K$865,"<="&Monthly_MIS!$B$6)-SUMIFS(Calc_Actuals!$O$2:$O$865,Calc_Actuals!$I$2:$I$865,$A11,Calc_Actuals!$C$2:$C$865,"Actual",Calc_Actuals!$J$2:$J$865,Monthly_MIS!$B$5,Calc_Actuals!$K$2:$K$865,"<="&Monthly_MIS!$B$6))/H11) -> 0.35320553 | L11: =IF(I11=0,"n/a",(SUMIFS(Calc_Actuals!$N$2:$N$865,Calc_Actuals!$I$2:$I$865,$A11,Calc_Actuals!$C$2:$C$865,"Actual",Calc_Actuals!$J$2:$J$865,(Monthly_MIS!$B$5-1),Calc_Actuals!$K$2:$K$865,"<="&Monthly_MIS!$B$6)-SUMIFS(Calc_Actuals!$O$2:$O$865,Calc_Actuals!$I$2:$I$865,$A11,Calc_Actuals!$C$2:$C$865,"Actual",Calc_Actuals!$J$2:$J$865,(Monthly_MIS!$B$5-1),Calc_Actuals!$K$2:$K$865,"<="&Monthly_MIS!$B$6))/I11) -> 0.33811202 | M11: =IFERROR((K11-L11)*100,"n/a") -> 1.5093515 | N11: =SUMPRODUCT(--(COUNTIFS(Calc_Actuals!$I$2:$I$865,$A11,Calc_Actuals!$F$2:$F$865,Region_Performance!$A$6:$A$9,Calc_Actuals!$C$2:$C$865,"Actual")>0)) -> 1
A12: Floor Cleaner | B12: Home Care | C12: =SUMIFS(Calc_Actuals!$N$2:$N$865,Calc_Actuals!$I$2:$I$865,$A12,Calc_Actuals!$C$2:$C$865,"Actual") -> 4633109.2 | D12: =SUMIFS(Calc_Actuals!$O$2:$O$865,Calc_Actuals!$I$2:$I$865,$A12,Calc_Actuals!$C$2:$C$865,"Actual") -> 2893839.8 | E12: =C12-D12 -> 1739269.4 | F12: =IF(C12=0,"n/a",E12/C12) -> 0.37540005 | G12: =C12/C$14 -> 0.10877624 | H12: =SUMIFS(Calc_Actuals!$N$2:$N$865,Calc_Actuals!$I$2:$I$865,$A12,Calc_Actuals!$C$2:$C$865,"Actual",Calc_Actuals!$J$2:$J$865,Monthly_MIS!$B$5,Calc_Actuals!$K$2:$K$865,"<="&Monthly_MIS!$B$6) -> 1978588.2 | I12: =SUMIFS(Calc_Actuals!$N$2:$N$865,Calc_Actuals!$I$2:$I$865,$A12,Calc_Actuals!$C$2:$C$865,"Actual",Calc_Actuals!$J$2:$J$865,(Monthly_MIS!$B$5-1),Calc_Actuals!$K$2:$K$865,"<="&Monthly_MIS!$B$6) -> 2076971.1 | J12: =IF(I12=0,"n/a",H12/I12-1) -> -0.047368473 | K12: =IF(H12=0,"n/a",(SUMIFS(Calc_Actuals!$N$2:$N$865,Calc_Actuals!$I$2:$I$865,$A12,Calc_Actuals!$C$2:$C$865,"Actual",Calc_Actuals!$J$2:$J$865,Monthly_MIS!$B$5,Calc_Actuals!$K$2:$K$865,"<="&Monthly_MIS!$B$6)-SUMIFS(Calc_Actuals!$O$2:$O$865,Calc_Actuals!$I$2:$I$865,$A12,Calc_Actuals!$C$2:$C$865,"Actual",Calc_Actuals!$J$2:$J$865,Monthly_MIS!$B$5,Calc_Actuals!$K$2:$K$865,"<="&Monthly_MIS!$B$6))/H12) -> 0.37311973 | L12: =IF(I12=0,"n/a",(SUMIFS(Calc_Actuals!$N$2:$N$865,Calc_Actuals!$I$2:$I$865,$A12,Calc_Actuals!$C$2:$C$865,"Actual",Calc_Actuals!$J$2:$J$865,(Monthly_MIS!$B$5-1),Calc_Actuals!$K$2:$K$865,"<="&Monthly_MIS!$B$6)-SUMIFS(Calc_Actuals!$O$2:$O$865,Calc_Actuals!$I$2:$I$865,$A12,Calc_Actuals!$C$2:$C$865,"Actual",Calc_Actuals!$J$2:$J$865,(Monthly_MIS!$B$5-1),Calc_Actuals!$K$2:$K$865,"<="&Monthly_MIS!$B$6))/I12) -> 0.37895158 | M12: =IFERROR((K12-L12)*100,"n/a") -> -0.58318482 | N12: =SUMPRODUCT(--(COUNTIFS(Calc_Actuals!$I$2:$I$865,$A12,Calc_Actuals!$F$2:$F$865,Region_Performance!$A$6:$A$9,Calc_Actuals!$C$2:$C$865,"Actual")>0)) -> 1
